Workbook
Name chinryo_list: '9賃料一覧'!$A$3:$T$1500
Name current_year: settings!$L$3
Name dt: pivot!$A$1
Name id_settings: settings!$A$2:$D$542
Name id2_asset: asset!$F$4:$CC$112
Name id3_asset_sum: asset!$B$2:$E$96
Name kariire_list: '5借入一覧'!$A$1:$AC$278
Name tax_capital: settings!$L$21
Name tax_income: settings!$L$19
Name 修繕明細: A.BM集計!$A$33:$J$291

Sheet sold
A1: 売却済み物件
F3: 減価償却 | BC3: 維持費用明細(税込) | BK3: 土地建物 筆の一覧 固定資産税評価額/固定資産税/都市計画税額
C4: 仙台駅前コーポ | D4: あおばマンション | F4: 1.物件ID | G4: 2.対象物件 | H4: 3.法人ID | I4: 4.法人名 | J4: 5.資産種類名 | K4: 6.償却方法 | L4: 7.資産名称 | M4: 8.取得年月日 | N4: 9.耐用年数 (年) | O4: 10.取得後経過年(目安) | P4: 11.残存耐用年(目安) | Q4: 12.取得価額 | R4: 13.期首帳簿価額 | S4: 14.年間償却額 | T4: 15.期末帳簿価額 | U4: 16.購入後の CAPEX | V4: 17.摘要 | X4: 1.連番 | Y4: 2.物件ID | Z4: 3.物件名 | AA4: 4.区画名 | AB4: 5.専有面積 | AC4: 6.クラスID | AD4: 7.クラス | AE4: 8.間取り | AF4: 9.賃料 | AG4: 10.共益費 | AH4: 11.その他 | AI4: 12.消費税 | AJ4: 13.現況賃料税込(自動) | AK4: 14.再募集賃料税抜 | AL4: 15.再募集賃料税 | AM4: 16.再募集税込(自動) | AN4: 17.満室想定税込(自動) | AO4: 18.入居者国籍 | AP4: 19.賃貸用 | AQ4: 20.メモ | AR4: sepa1 | AS4: 31.区画ID | AT4: 32.購入時賃料税抜 | AU4: sepa2 | AV4: 41.入居中判定 | AW4: 42.満室想定税抜(自動) | AX4: 43.賃料増減余地(自動) | AY4: 44.購入後の賃料増加額税抜（自動） | AZ4: 45.物理区画判定(自動) | BA4: 46.論理区画判定(自動) | BC4: 物件ID | BD4: 物件名 | BE4: BM費用ID | BF4: BM費用項目(自動) | BG4: 月額合計 | BH4: 年換算(×12) | BI4: 摘要 | BK4: 連番 | BL4: 物件 ID | BM4: 物件名 | BN4: 資産クラスID | BO4: 資産クラス | BP4: 地番 | BQ4: 家屋番号 | BR4: 所有/ 借地権 | BS4: 面積ネット (持分按分後の実質) | BT4: 面積グロス (評価証明上の表記) | BU4: 共有持分 分子 | BV4: 共有持分 分母 | BW4: 区分 分子 | BX4: 区分 分母 | BY4: 当該資産 評価額 | BZ4: 当期固定資産税額 | CA4: 当期都市計画税額
A5: 11 | B5: 物件ID | C5: 110 | D5: 118
A6: 12 | B6: 物件概要
A7: 13 | B7: 現所有者 | C7: 410 | D7: 410
A8: 14 | B8: 交通 | C8: コアプラス沖縄株式会社 | D8: コアプラス沖縄株式会社
A9: 15 | B9: 住所 | C9: 東北本線「仙台」歩10分 | D9: 田園都市線「青葉台」歩5分
A10: 16 | B10: 一棟or区分 | C10: 宮城県仙台市宮城野区名掛丁991-55 | D10: 神奈川県横浜市青葉区青葉台9-25-1
A11: 17 | B11: 権利形態 | C11: 一棟 | D11: 一棟
A12: 18 | B12: 土地面積 | C12: 313.11 | D12: 732.25
A13: 19 | B13: 土地面積（坪） | C13: 94.715635 | D13: 221.5053
A14: 20 | B14: 建物のべ床 | C14: 528.43 | D14: 1110.34
A15: 21 | B15: 建物構造 | C15: 所有権 | D15: 所有権
A16: 22 | B16: 建物築年 | C16: RC/B1-5F | D16: RC/B1-5F
A17: 23 | B17: 建物経過年数 | C17: 31 | D17: 28
A18: 24 | B18: 総区画数 | C18: 24 | D18: 36
A19: 25 | B19: うち住居数 | C19: 22 | D19: 34
A20: 26 | B20: うち事務所/店舗数 | C20: 1 | D20: 0
A21: 27 | B21: うち駐車場 | C21: 0 | D21: 2
A22: 28 | B22: うちその他 | C22: 1 | D22: 0
A23: 29 | B23: 用途と計画 | C23: 34824 | D23: 34100
A24: 30 | B24: 購入年月 | C24: 44624 | D24: 44348
A25: 31 | B25: 購入価格 | C25: 227000000 | D25: 415000000
A26: 32 | B26: 物件メモ
A27: 91 | B27: 売却価格 | C27: 227000000 | D27: 415000000
A28: 92 | B28: 売却益概算 | C28: 30000000 | D28: 30000000
A29: 93 | B29: 売却時利回り | C29: 0.065 | D29: 0.07

Sheet pivot
A1: ピボットテーブルの一覧 | J1: Pivot1 | W1: Pivot2 | AC1: Pivot3 | AI1: Pivot4 | AR1: Pivot5 | BF1: Pivot8 | BT1: Pivot19 | CF1: Pivot9 | CJ1: Pivot10 | CO1: Pivot11 | DB1: Pivot12 | DF1: Pivot13 | DJ1: Pivot14 | DY1: Pivot15 | EG1: Pivot16 | EM1: Pivot17 | ES1: Pivot18 | FN1: Pivot20
A2: ピボット番号 | B2: リンク | C2: シート | D2: 項目 | E2: 条件1 | F2: 設定1 | G2: 条件2 | H2: 設定2 | J2: BM費用集計 | W2: 取得時簿価 | AC2: 2022年期首簿価 | AI2: 2022年(1年間)の償却額 | AR2: 満室想定賃料(税込・月額) | BF2: 現況賃料(税込・月額) | BT2: 現況賃料(税込・月額) | CF2: 資産クラス別（非賃貸を除く）金額ベース入居率 | CJ2: 賃料増減の推移(非賃貸を含む・月額) | CO2: 大口テナントの一覧(非賃貸を含む) | DB2: 賃貸用資産（非賃貸を除く）の賃料帯別ヒストグラム | DF2: 賃貸用資産（非賃貸を除く）の賃料帯別ヒストグラム | DJ2: 土地建物 筆の一覧 固定資産税評価額/固定資産税/都市計画税額 | DY2: 24 | DZ2: 総区画数 | EG2: C41 | EH2: ='3物件一覧'!B34 -> 残債2022年11月5日現在 | EM2: グループ全体P/L | ES2: 3物件一覧 | FN2: 5借入一覧
A3: Pivot1 | B3: =HYPERLINK("#pivot!"&ADDRESS(1,MATCH(A3,$A$1:$GE$1,0),4),A3) -> Pivot1 | C3: A.BM集計 | D3: BM費用集計 | J3: A.BM集計 | W3: 6減価償却 | AC3: 6減価償却 | AI3: 6減価償却 | AR3: 8賃料集計 | BF3: 8賃料集計 | BT3: 8賃料集計 | CF3: 8賃料集計 | CJ3: 8賃料集計 | CO3: 8賃料集計 | DB3: 住居系 | DC3: 8賃料集計 | DF3: 事務所・店舗系 | DG3: 8賃料集計 | DJ3: B筆一覧 | DY3: 3物件一覧 | EG3: 3物件一覧 | EH3: 対象物件 | EM3: 2法人連結 | ES3: 共同担保の提供状況 | FN3: 当初借入額集計
A4: Pivot2 | B4: =HYPERLINK("#pivot!"&ADDRESS(1,MATCH(A4,$A$1:$GE$1,0),4),A4) -> Pivot2 | C4: 6減価償却 | D4: 取得時簿価 | E4: 16.購入後の CAPEX | F4: 0 | J4: BM集計 | W4: 償却1 | AC4: 償却2 | AI4: 償却3 | AR4: 賃料1 | BF4: 賃料2 | BG4: 2002 | BT4: 賃料3 | BU4: 2004 | CF4: 46.論理区画判定(自動) | CG4: 1 | CJ4: 46.論理区画判定(自動) | CK4: 1 | DB4: 46.論理区画判定(自動) | DC4: 1 | DY4: 45.物理区画判定(自動) | DZ4: 1 | EG4: 行ラベル | EH4: 合計 / 22.元金返済月額 | EI4: 合計 / 23.利息月額 | EJ4: 合計 / 24.支払月額 | EK4: 合計 / 25.残債 | FN4: 2.状況 | FO4: 返済中
A5: Pivot3 | B5: =HYPERLINK("#pivot!"&ADDRESS(1,MATCH(A5,$A$1:$GE$1,0),4),A5) -> Pivot3 | C5: 6減価償却 | D5: 2022年期首簿価 | J5: 合計 / 年換算(×12) | K5: 列ラベル | W5: 16.購入後の CAPEX | X5: (複数のアイテム) | AC5: 合計 / 13.期首帳簿価額 | AD5: 列ラベル | AI5: 合計 / 14.年間償却額 | AJ5: 列ラベル | AR5: 賃貸用yes+noのすべて | AS5: 2001 | BF5: 46.論理区画判定(自動) | BG5: 1 | BT5: 46.論理区画判定(自動) | BU5: 1 | CF5: 19.賃貸用 | CG5: yes | CO5: 46.論理区画判定(自動) | CP5: 1 | DB5: 7.クラス | DC5: 住居 | DF5: 46.論理区画判定(自動) | DG5: 1 | DK5: 列ラベル | EG5: あおばマンション | EZ5: 671 | FA5: 672 | FB5: 673 | FC5: 674 | FD5: 675
A6: Pivot4 | B6: =HYPERLINK("#pivot!"&ADDRESS(1,MATCH(A6,$A$1:$GE$1,0),4),A6) -> Pivot4 | C6: 6減価償却 | D6: 2022年(1年間)の償却額 | J6: 行ラベル | K6: 建物管理料 | L6: 電気料金(電灯) | M6: 電気料金(低圧) | N6: その他 | O6: 火災保険料 | P6: 水道料金 | Q6: 区分管理費 | R6: 区分修繕積立金 | S6: (空白) | T6: 立替金 | U6: 総計 | AD6: 建物等 | AE6: 土地 | AF6: (空白) | AG6: 総計 | AI6: 行ラベル | AJ6: 器具備品 | AK6: 建物 | AL6: 建物附属設備 | AM6: 構築物 | AN6: 土地 | AO6: (空白) | AP6: 総計 | BT6: 19.賃貸用 | BU6: yes | CJ6: 行ラベル | CK6: 合計 / 32.購入時賃料税抜 | CL6: 合計 / 42.満室想定税抜(自動) | CM6: 合計 / 14.再募集賃料税抜 | DB6: 19.賃貸用 | DC6: yes | DF6: 19.賃貸用 | DG6: yes | DK6: 建物 | DO6: 土地3種 | DS6: 全体の 合計 / 面積ネット (持分按分後の実質) | DT6: 全体の 合計 / 当該資産 評価額 | DU6: 全体の 合計 / 当期固定資産税額 | DV6: 全体の 合計 / 当期都市計画税額 | DY6: 合計 / 45.物理区画判定(自動) | DZ6: 列ラベル | EG6: カーサ南池袋 | EH6: 437860 | EI6: 183356 | EJ6: 621216 | EK6: 146247653 | EY6: 1 | EZ6: 2 | FA6: 3 | FB6: 4 | FC6: 5 | FD6: 6 | FE6: 7 | FF6: 8 | FG6: 9 | FH6: 10 | FI6: 11 | FJ6: 12 | FK6: 13 | FL6: 14 | FN6: 行ラベル | FO6: 合計 / 14.当初借入額
A7: Pivot5 | B7: =HYPERLINK("#pivot!"&ADDRESS(1,MATCH(A7,$A$1:$GE$1,0),4),A7) -> Pivot5 | C7: 8賃料集計 | D7: 満室想定賃料(税込・月額) | E7: 賃貸用 | F7: yes+noのすべて | G7: 論理区画 | H7: あり | J7: カーサ南池袋 | K7: 394680 | L7: 210756 | M7: 84480 | O7: 12950 | U7: 702866 | W7: 合計 / 12.12.取得価額 | X7: 列ラベル | AC7: 行ラベル | AI7: カーサ南池袋 | AJ7: 88704 | AK7: 2967179 | AL7: 1454309 | AP7: 4510192 | AR7: 46.論理区画判定(自動) | AS7: 1 | BF7: 合計 / 13.現況賃料税込(自動) | BG7: 列ラベル | CF7: 行ラベル | CG7: 合計 / 17.満室想定税込(自動) | CH7: 合計 / 13.現況賃料税込(自動) | CJ7: カーサ南池袋 | CK7: 1402284 | CL7: 1523829 | CM7: 1519127 | CO7: 行ラベル | CP7: 合計 / 17.満室想定税込(自動) | CQ7: 合計 / 17.満室想定税込(自動)2 | CS7: 序列 | CT7: ID | CU7: 物件名 | CV7: 区画名 | CW7: クラス | CX7: 間取り | CY7: 満室想定税込(自動) | DZ7: 店舗事務所系物理区画 | EA7: アンテナ | EB7: 住居 | EC7: 倉庫 | ED7: 駐車場 | EE7: 総計 | EG7: カーサ目白台ハウス | EH7: 1049552 | EI7: 299492 | EJ7: 1349044 | EK7: 325693047 | EM7: 行ラベル | EN7: 合計 / 22.元金返済月額 | EO7: 合計 / 23.利息月額 | EP7: 合計 / 24.支払月額 | EQ7: 合計 / 25.残債 | ES7: 連番 | ET7: 担保提供種別ID | EU7: 共同担保物件ID | EV7: 行番号 | EW7: データ | EX7: 列 | EY7: 物件ID | EZ7: 共同担保, | FA7: 第一抵当, | FB7: 第二抵当, | FC7: 第三抵当, | FD7: 第四抵当, | FE7: 出力1 | FF7: 出力2 | FG7: 出力3 | FH7: 出力4 | FI7: 出力5 | FJ7: 文字列結合1 | FK7: 文字列結合2 | FL7: 文字列結合3 | FN7: 運転資金 | FO7: 11000000
A8: Pivot6 | B8: 削除 | C8: 8賃料集計 | D8: 満室想定賃料(税込・月額) | E8: 賃貸用 | F8: yesのみ | G8: 論理区画 | H8: あり | J8: カーサ目白台ハウス | K8: 1457280 | L8: 151992 | M8: 286488 | O8: 19430 | P8: 18744 | U8: 1933934 | X8: 建物等 | Y8: 土地 | Z8: (空白) | AA8: 総計 | AC8: カーサ南池袋 | AD8: 27798216 | AE8: 165375617 | AG8: 193173833 | AI8: カーサ目白台ハウス | AK8: 5828706 | AL8: 181266 | AP8: 6009972 | BF8: 行ラベル | BG8: アンテナ | BH8: その他 | BI8: 事務所 | BJ8: 自販機 | BK8: 住居 | BL8: 倉庫 | BM8: 駐車場 | BN8: 店舗 | BO8: (空白) | BP8: 総計 | BT8: 合計 / 13.現況賃料税込(自動) | BU8: 列ラベル | CF8: アンテナ | CG8: 247035 | CH8: 247035 | CJ8: カーサ目白台ハウス | CK8: 2898715 | CL8: 2944145 | CM8: 2929143 | CO8: 208 | CP8: 2530000 | CQ8: 1 | CS8: 1 | CT8: =VLOOKUP($CO8,chinryo_list,2,FALSE) -> 112 | CU8: =VLOOKUP($CO8,chinryo_list,3,FALSE) -> 豊島目白ビル | CV8: =VLOOKUP($CO8,chinryo_list,4,FALSE) -> 101 | CW8: =VLOOKUP($CO8,chinryo_list,7,FALSE) -> 事務所 | CX8: =VLOOKUP($CO8,chinryo_list,8,FALSE) -> 事務所 | CY8: =VLOOKUP($CO8,chinryo_list,17,FALSE) -> 2530000 | DB8: 行ラベル | DC8: 個数 / 17.満室想定税込(自動) | DD8: 合計 / 17.満室想定税込(自動)2 | DF8: 行ラベル | DG8: 個数 / 17.満室想定税込(自動) | DH8: 合計 / 17.満室想定税込(自動)2 | DJ8: 行ラベル | DK8: 合計 / 面積ネット (持分按分後の実質) | DL8: 合計 / 当該資産 評価額 | DM8: 合計 / 当期固定資産税額 | DN8: 合計 / 当期都市計画税額 | DO8: 合計 / 面積ネット (持分按分後の実質) | DP8: 合計 / 当該資産 評価額 | DQ8: 合計 / 当期固定資産税額 | DR8: 合計 / 当期都市計画税額 | DY8: 行ラベル | EA8: アンテナ | EB8: 住居 | EC8: 倉庫 | ED8: 駐車場 | EG8: コアプラスレジデンス梅田 | EH8: 738310 | EI8: 406469 | EJ8: 1144779 | EK8: 338136161 | EM8: 間接部門 | EN8: 338579 | EO8: 253711 | EP8: 592290 | EQ8: 113947016 | ES8: 1 | ET8: AG | EU8: AE | EV8: 2 | EW8: {=INDIRECT("'5借入一覧'!"&ET8&EV8)&INDIRECT("'5借入一覧'!"&EU8&EV8)} | EX8: 1 | EY8: 1 | EZ8: =VLOOKUP($EY8&EZ$5,$EW$7:$EX$1101,2,FALSE) -> #N/A | FA8: =VLOOKUP($EY8&FA$5,$EW$7:$EX$1101,2,FALSE) -> #N/A | FB8: =VLOOKUP($EY8&FB$5,$EW$7:$EX$1101,2,FALSE) -> #N/A | FC8: =VLOOKUP($EY8&FC$5,$EW$7:$EX$1101,2,FALSE) -> #N/A | FD8: =VLOOKUP($EY8&FD$5,$EW$7:$EX$1101,2,FALSE) -> #N/A | FE8: =IFERROR(IF(EZ8>0,EZ$7),"") | FF8: =IFERROR(IF(FA8>0,FA$7),"") | FG8: =IFERROR(IF(FB8>0,FB$7),"") | FH8: =IFERROR(IF(FC8>0,FC$7),"") | FI8: =IFERROR(IF(FD8>0,FD$7),"") | FJ8: =FE8&FF8&FG8&FH8&FI8 | FK8: =IF(FJ8<>"",LEFT(FJ8,LEN(FJ8)-1),"") | FL8: =IF(FK8<>"",FK8&"として提供中","無") -> 無 | FN8: 対象物件なし(運転資金) | FO8: 11000000
A9: Pivot7 | B9: 削除 | C9: 8賃料集計 | D9: 満室想定賃料(税込・月額) | E9: 賃貸用 | F9: noのみ | G9: 論理区画 | H9: あり | J9: コアプラスレジデンス梅田 | K9: 1160280 | L9: 101808 | M9: 259500 | N9: 132000 | O9: 20620 | P9: 22836 | U9: 1697044 | W9: 行ラベル | AC9: カーサ目白台ハウス | AD9: 113300805 | AE9: 264084489 | AG9: 377385294 | AI9: コアプラスレジデンス梅田 | AJ9: 83013 | AK9: 7073962 | AL9: 705692 | AP9: 7862667 | AR9: 合計 / 17.満室想定税込(自動) | AS9: 列ラベル | BF9: カーサ南池袋 | BG9: 72911 | BH9: 0 | BK9: 1417000 | BL9: 17600 | BM9: 27000 | BP9: 1534511 | BT9: 行ラベル | BU9: アンテナ | BV9: 事務所 | BW9: 自販機 | BX9: 住居 | BY9: 倉庫 | BZ9: 駐車場 | CA9: 店舗 | CB9: 総計 | CF9: その他 | CJ9: コアプラスレジデンス梅田 | CK9: 2282000 | CL9: 2429000 | CM9: 2341000 | CO9: 184 | CP9: 1758634 | CQ9: 2 | CS9: 2 | CT9: =VLOOKUP($CO9,chinryo_list,2,FALSE) -> 111 | CU9: =VLOOKUP($CO9,chinryo_list,3,FALSE) -> 目白カーサ二番館 | CV9: =VLOOKUP($CO9,chinryo_list,4,FALSE) -> SL1 | CW9: =VLOOKUP($CO9,chinryo_list,7,FALSE) -> 住居 | CX9: =VLOOKUP($CO9,chinryo_list,8,FALSE) -> 1K | CY9: =VLOOKUP($CO9,chinryo_list,17,FALSE) -> 1758634 | DB9: <0 または (空白) | DF9: <0 または (空白) | DJ9: カーサ南池袋 | DK9: 588.5 | DL9: 15015300 | DM9: 210214 | DN9: 45045 | DO9: 252.09 | DP9: 123284110 | DQ9: 249401 | DR9: 53443 | DS9: 840.59 | DT9: 138299410 | DU9: 459615 | DV9: 98488 | DY9: カーサ南池袋 | EA9: 2 | EB9: 12 | EC9: 1 | ED9: 1 | EE9: 16 | EG9: コアプラス大塚 | EH9: 902892 | EI9: 513702 | EJ9: 1416594 | EK9: 473298872 | EM9: その他(間接部門) | ES9: 2 | ET9: AG | EU9: AE | EV9: 3 | EW9: {=INDIRECT("'5借入一覧'!"&ET9&EV9)&INDIRECT("'5借入一覧'!"&EU9&EV9)} | EX9: 1 | EY9: 2 | EZ9: =VLOOKUP($EY9&EZ$5,$EW$7:$EX$1101,2,FALSE) -> #N/A | FA9: =VLOOKUP($EY9&FA$5,$EW$7:$EX$1101,2,FALSE) -> #N/A | FB9: =VLOOKUP($EY9&FB$5,$EW$7:$EX$1101,2,FALSE) -> #N/A | FC9: =VLOOKUP($EY9&FC$5,$EW$7:$EX$1101,2,FALSE) -> #N/A | FD9: =VLOOKUP($EY9&FD$5,$EW$7:$EX$1101,2,FALSE) -> #N/A | FE9: =IFERROR(IF(EZ9>0,EZ$7),"") | FF9: =IFERROR(IF(FA9>0,FA$7),"") | FG9: =IFERROR(IF(FB9>0,FB$7),"") | FH9: =IFERROR(IF(FC9>0,FC$7),"") | FI9: =IFERROR(IF(FD9>0,FD$7),"") | FJ9: =FE9&FF9&FG9&FH9&FI9 | FK9: =IF(FJ9<>"",LEFT(FJ9,LEN(FJ9)-1),"") | FL9: =IF(FK9<>"",FK9&"として提供中","無") -> 無 | FN9: 修繕資金 | FO9: 63456000
A10: Pivot8 | B10: =HYPERLINK("#pivot!"&ADDRESS(1,MATCH(A10,$A$1:$GE$1,0),4),A10) -> Pivot8 | C10: 8賃料集計 | D10: 現況賃料(税込・月額) | E10: 賃貸用 | F10: yes+noのすべて | G10: 論理区画 | H10: あり | J10: コアプラス大塚 | K10: 1301520 | L10: 240684 | M10: 295140 | O10: 34430 | P10: 45672 | U10: 1917446 | W10: カーサ南池袋 | X10: 26492683 | Y10: 165375617 | AA10: 191868300 | AC10: コアプラスレジデンス梅田 | AD10: 152141411 | AE10: 211645475 | AG10: 363786886 | AI10: コアプラス大塚 | AK10: 7773951 | AP10: 7773951 | AR10: 行ラベル | AS10: アンテナ | AT10: その他 | AU10: 事務所 | AV10: 自販機 | AW10: 住居 | AX10: 倉庫 | AY10: 駐車場 | AZ10: 店舗 | BA10: (空白) | BB10: 総計 | BF10: カーサ目白台ハウス | BI10: 643878 | BK10: 1913800 | BM10: 126500 | BN10: 363000 | BP10: 3047178 | BT10: カーサ南池袋 | BU10: 72911 | BX10: 1417000 | BY10: 17600 | BZ10: 27000 | CB10: 1534511 | CF10: 事務所 | CG10: 3737978 | CH10: 3702978 | CJ10: コアプラス大塚 | CK10: 3143630 | CL10: 3521704 | CM10: 3495703 | CO10: 165 | CP10: 1100000 | CQ10: 3 | CS10: 3 | CT10: =VLOOKUP($CO10,chinryo_list,2,FALSE) -> 107 | CU10: =VLOOKUP($CO10,chinryo_list,3,FALSE) -> メゾン雑司ヶ谷 | CV10: =VLOOKUP($CO10,chinryo_list,4,FALSE) -> 1F | CW10: =VLOOKUP($CO10,chinryo_list,7,FALSE) -> 店舗 | CX10: =VLOOKUP($CO10,chinryo_list,8,FALSE) -> 店舗 | CY10: =VLOOKUP($CO10,chinryo_list,17,FALSE) -> 1100000 | DB10: 0-9999 | DF10: アンテナ | DJ10: カーサ目白台ハウス | DK10: 887.19 | DL10: 58425900 | DM10: 817962 | DN10: 175277 | DO10: 395.33 | DP10: 176328930 | DQ10: 519513 | DR10: 111323 | DS10: 1282.52 | DT10: 234754830 | DU10: 1337475 | DV10: 286600 | DY10: カーサ目白台ハウス | DZ10: 6 | EB10: 9 | ED10: 3 | EE10: 18 | EG10: コアプラス池袋 | EH10: 328928 | EI10: 58976 | EJ10: 387904 | EK10: 70446823 | EM10: あおばマンション | ES10: 3 | ET10: AG | EU10: AE | EV10: 4 | EW10: {=INDIRECT("'5借入一覧'!"&ET10&EV10)&INDIRECT("'5借入一覧'!"&EU10&EV10)} | EX10: 1 | EY10: 3 | EZ10: =VLOOKUP($EY10&EZ$5,$EW$7:$EX$1101,2,FALSE) -> #N/A | FA10: =VLOOKUP($EY10&FA$5,$EW$7:$EX$1101,2,FALSE) -> #N/A | FB10: =VLOOKUP($EY10&FB$5,$EW$7:$EX$1101,2,FALSE) -> #N/A | FC10: =VLOOKUP($EY10&FC$5,$EW$7:$EX$1101,2,FALSE) -> #N/A | FD10: =VLOOKUP($EY10&FD$5,$EW$7:$EX$1101,2,FALSE) -> #N/A | FE10: =IFERROR(IF(EZ10>0,EZ$7),"") | FF10: =IFERROR(IF(FA10>0,FA$7),"") | FG10: =IFERROR(IF(FB10>0,FB$7),"") | FH10: =IFERROR(IF(FC10>0,FC$7),"") | FI10: =IFERROR(IF(FD10>0,FD$7),"") | FJ10: =FE10&FF10&FG10&FH10&FI10 | FK10: =IF(FJ10<>"",LEFT(FJ10,LEN(FJ10)-1),"") | FL10: =IF(FK10<>"",FK10&"として提供中","無") -> 無 | FN10: コアプラスレジデンス梅田 | FO10: 15000000
A11: Pivot9 | B11: =HYPERLINK("#pivot!"&ADDRESS(1,MATCH(A11,$A$1:$GE$1,0),4),A11) -> Pivot9 | C11: 8賃料集計 | D11: 資産クラス別（非賃貸を除く）金額ベース入居率 | G11: 論理区画 | H11: あり | J11: コアプラス池袋 | K11: 376200 | L11: 12372 | O11: 6600 | P11: 22836 | U11: 418008 | W11: カーサ目白台ハウス | X11: 149454010 | Y11: 264084489 | AA11: 413538499 | AC11: コアプラス大塚 | AD11: 213808751 | AE11: 300927161 | AG11: 514735912 | AI11: コアプラス池袋 | AK11: 864458 | AL11: 409639 | AM11: 60741 | AP11: 1334838 | AR11: no | AT11: 0 | AW11: 295000 | BB11: 295000 | BF11: コアプラスレジデンス梅田 | BG11: 13200 | BH11: 0 | BK11: 2041000 | BN11: 413600 | BP11: 2467800 | BT11: カーサ目白台ハウス | BV11: 643878 | BX11: 1913800 | BZ11: 126500 | CA11: 363000 | CB11: 3047178 | CF11: 自販機 | CG11: 0 | CH11: 0 | CJ11: コアプラス池袋 | CK11: 620000 | CL11: 722000 | CM11: 729000 | CO11: 292 | CP11: 413600 | CQ11: 4 | CS11: 4 | CT11: =VLOOKUP($CO11,chinryo_list,2,FALSE) -> 116 | CU11: =VLOOKUP($CO11,chinryo_list,3,FALSE) -> コアプラスレジデンス梅田 | CV11: =VLOOKUP($CO11,chinryo_list,4,FALSE) -> 101 | CW11: =VLOOKUP($CO11,chinryo_list,7,FALSE) -> 店舗 | CX11: =VLOOKUP($CO11,chinryo_list,8,FALSE) -> 店舗 | CY11: =VLOOKUP($CO11,chinryo_list,17,FALSE) -> 413600 | DB11: 10000-19999 | DF11: その他 | DJ11: コアプラスレジデンス梅田 | DK11: 966.35 | DL11: 53982400 | DM11: 755753 | DN11: 161947 | DO11: 207.8 | DP11: 114941450 | DQ11: 210432 | DR11: 45092 | DS11: 1174.15 | DT11: 168923850 | DU11: 966185 | DV11: 207039 | DY11: コアプラスレジデンス梅田 | DZ11: 1 | EA11: 1 | EB11: 14 | EE11: 16 | EG11: メゾン雑司ヶ谷 | EH11: 982474 | EI11: 314688 | EJ11: 1297162 | EK11: 313706389 | EM11: カーサ南池袋 | ES11: 4 | ET11: AG | EU11: AE | EV11: 5 | EW11: {=INDIRECT("'5借入一覧'!"&ET11&EV11)&INDIRECT("'5借入一覧'!"&EU11&EV11)} | EX11: 1 | EY11: 4 | EZ11: =VLOOKUP($EY11&EZ$5,$EW$7:$EX$1101,2,FALSE) -> #N/A | FA11: =VLOOKUP($EY11&FA$5,$EW$7:$EX$1101,2,FALSE) -> #N/A | FB11: =VLOOKUP($EY11&FB$5,$EW$7:$EX$1101,2,FALSE) -> #N/A | FC11: =VLOOKUP($EY11&FC$5,$EW$7:$EX$1101,2,FALSE) -> #N/A | FD11: =VLOOKUP($EY11&FD$5,$EW$7:$EX$1101,2,FALSE) -> #N/A | FE11: =IFERROR(IF(EZ11>0,EZ$7),"") | FF11: =IFERROR(IF(FA11>0,FA$7),"") | FG11: =IFERROR(IF(FB11>0,FB$7),"") | FH11: =IFERROR(IF(FC11>0,FC$7),"") | FI11: =IFERROR(IF(FD11>0,FD$7),"") | FJ11: =FE11&FF11&FG11&FH11&FI11 | FK11: =IF(FJ11<>"",LEFT(FJ11,LEN(FJ11)-1),"") | FL11: =IF(FK11<>"",FK11&"として提供中","無") -> 無 | FN11: プラウD目白301号 | FO11: 20556000
A12: Pivot10 | B12: =HYPERLINK("#pivot!"&ADDRESS(1,MATCH(A12,$A$1:$GE$1,0),4),A12) -> Pivot10 | C12: 8賃料集計 | D12: 賃料増減の推移(非賃貸を含む・月額) | G12: 論理区画 | H12: あり | J12: ビジネス新大阪123号 | O12: 2060 | Q12: 48600 | R12: 16200 | U12: 66860 | W12: コアプラスレジデンス梅田 | X12: 147620954 | Y12: 211645475 | AA12: 359266429 | AC12: コアプラス池袋 | AD12: 29536448 | AE12: 78084258 | AG12: 107620706 | AI12: ビジネス新大阪123号 | AK12: 256421 | AP12: 256421 | AR12: カーサ南池袋 | AT12: 0 | BB12: 0 | BF12: コアプラス大塚 | BG12: 13200 | BH12: 0 | BK12: 3011000 | BM12: 356481 | BN12: 192093 | BP12: 3572774 | BT12: コアプラスレジデンス梅田 | BU12: 13200 | BX12: 2041000 | CA12: 413600 | CB12: 2467800 | CF12: 住居 | CG12: 28235436 | CH12: 27943232 | CJ12: ビジネス新大阪123号 | CK12: 35000 | CL12: 35000 | CM12: 35000 | CO12: 275 | CP12: 356481 | CQ12: 5 | CS12: 5 | CT12: =VLOOKUP($CO12,chinryo_list,2,FALSE) -> 115 | CU12: =VLOOKUP($CO12,chinryo_list,3,FALSE) -> コアプラス大塚 | CV12: =VLOOKUP($CO12,chinryo_list,4,FALSE) -> BF1 | CW12: =VLOOKUP($CO12,chinryo_list,7,FALSE) -> 駐車場 | CX12: =VLOOKUP($CO12,chinryo_list,8,FALSE) -> 駐車場 | CY12: =VLOOKUP($CO12,chinryo_list,17,FALSE) -> 356481 | DB12: 20000-29999 | DF12: 事務所 | DJ12: コアプラス大塚 | DK12: 1490.43 | DL12: 123562400 | DM12: 1729873 | DN12: 370687 | DO12: 443.07 | DP12: 174271390 | DQ12: 363928 | DR12: 77984 | DS12: 1933.5 | DT12: 297833790 | DU12: 2093801 | DV12: 448671 | DY12: コアプラス大塚 | DZ12: 1 | EA12: 1 | EB12: 23 | ED12: 1 | EE12: 26 | EG12: レジデンス目白豊島 | EH12: 324776 | EI12: 180387 | EJ12: 505163 | EK12: 166191734 | EM12: カーサ目白台ハウス | ES12: 5 | ET12: AG | EU12: AE | EV12: 6 | EW12: {=INDIRECT("'5借入一覧'!"&ET12&EV12)&INDIRECT("'5借入一覧'!"&EU12&EV12)} | EX12: 1 | EY12: 5 | EZ12: =VLOOKUP($EY12&EZ$5,$EW$7:$EX$1101,2,FALSE) -> #N/A | FA12: =VLOOKUP($EY12&FA$5,$EW$7:$EX$1101,2,FALSE) -> #N/A | FB12: =VLOOKUP($EY12&FB$5,$EW$7:$EX$1101,2,FALSE) -> #N/A | FC12: =VLOOKUP($EY12&FC$5,$EW$7:$EX$1101,2,FALSE) -> #N/A | FD12: =VLOOKUP($EY12&FD$5,$EW$7:$EX$1101,2,FALSE) -> #N/A | FE12: =IFERROR(IF(EZ12>0,EZ$7),"") | FF12: =IFERROR(IF(FA12>0,FA$7),"") | FG12: =IFERROR(IF(FB12>0,FB$7),"") | FH12: =IFERROR(IF(FC12>0,FC$7),"") | FI12: =IFERROR(IF(FD12>0,FD$7),"") | FJ12: =FE12&FF12&FG12&FH12&FI12 | FK12: =IF(FJ12<>"",LEFT(FJ12,LEN(FJ12)-1),"") | FL12: =IF(FK12<>"",FK12&"として提供中","無") -> 無 | FN12: 目白アパート | FO12: 17900000
A13: Pivot11 | B13: =HYPERLINK("#pivot!"&ADDRESS(1,MATCH(A13,$A$1:$GE$1,0),4),A13) -> Pivot11 | C13: 8賃料集計 | D13: 大口テナントの一覧(非賃貸を含む) | G13: 論理区画 | H13: あり | J13: プラウD目白301号室 | W13: コアプラス大塚 | X13: 250772634 | Y13: 300927161 | AA13: 551699795 | AC13: ビジネス新大阪123号 | AD13: 2797363 | AE13: 2488575 | AG13: 5285938 | AI13: プラウD目白301号室 | AR13: カーサ目白台ハウス | BF13: コアプラス池袋 | BI13: 132000 | BK13: 367000 | BN13: 169400 | BP13: 668400 | BT13: コアプラス大塚 | BU13: 13200 | BX13: 3011000 | BZ13: 356481 | CA13: 192093 | CB13: 3572774 | CF13: 倉庫 | CG13: 282415 | CH13: 282415 | CJ13: メゾン雑司ヶ谷 | CK13: 2404000 | CL13: 2378700 | CM13: 2391700 | CO13: 317 | CP13: 330000 | CQ13: 6 | CS13: 6 | CT13: =VLOOKUP($CO13,chinryo_list,2,FALSE) -> 121 | CU13: =VLOOKUP($CO13,chinryo_list,3,FALSE) -> 目白アパート1号館 | CV13: =VLOOKUP($CO13,chinryo_list,4,FALSE) -> 101 | CW13: =VLOOKUP($CO13,chinryo_list,7,FALSE) -> 住居 | CX13: =VLOOKUP($CO13,chinryo_list,8,FALSE) -> 2LDK | CY13: =VLOOKUP($CO13,chinryo_list,17,FALSE) -> 330000 | DB13: 30000-39999 | DF13: 自販機 | DJ13: コアプラス池袋 | DK13: 177.12 | DL13: 8669000 | DM13: 121366 | DN13: 26007 | DO13: 137.3 | DP13: 57534050 | DQ13: 109261 | DR13: 23413 | DS13: 314.42 | DT13: 66203050 | DU13: 230627 | DV13: 49420 | DY13: コアプラス池袋 | DZ13: 2 | EB13: 6 | EE13: 8 | EG13: 高田馬場第4玉川ビル | EH13: 224843 | EI13: 146653 | EJ13: 371496 | EK13: 104842675 | EM13: コアプラスレジデンス梅田 | ES13: 6 | ET13: AG | EU13: AE | EV13: 7 | EW13: {=INDIRECT("'5借入一覧'!"&ET13&EV13)&INDIRECT("'5借入一覧'!"&EU13&EV13)} | EX13: 1 | EY13: 6 | EZ13: =VLOOKUP($EY13&EZ$5,$EW$7:$EX$1101,2,FALSE) -> #N/A | FA13: =VLOOKUP($EY13&FA$5,$EW$7:$EX$1101,2,FALSE) -> #N/A | FB13: =VLOOKUP($EY13&FB$5,$EW$7:$EX$1101,2,FALSE) -> #N/A | FC13: =VLOOKUP($EY13&FC$5,$EW$7:$EX$1101,2,FALSE) -> #N/A | FD13: =VLOOKUP($EY13&FD$5,$EW$7:$EX$1101,2,FALSE) -> #N/A | FE13: =IFERROR(IF(EZ13>0,EZ$7),"") | FF13: =IFERROR(IF(FA13>0,FA$7),"") | FG13: =IFERROR(IF(FB13>0,FB$7),"") | FH13: =IFERROR(IF(FC13>0,FC$7),"") | FI13: =IFERROR(IF(FD13>0,FD$7),"") | FJ13: =FE13&FF13&FG13&FH13&FI13 | FK13: =IF(FJ13<>"",LEFT(FJ13,LEN(FJ13)-1),"") | FL13: =IF(FK13<>"",FK13&"として提供中","無") -> 無 | FN13: 目白アパート1号館 | FO13: 10000000
A14: Pivot12 | B14: =HYPERLINK("#pivot!"&ADDRESS(1,MATCH(A14,$A$1:$GE$1,0),4),A14) -> Pivot12 | C14: 8賃料集計 | D14: 住居系_賃貸用資産（非賃貸を除く）の賃料帯別ヒストグラム | E14: クラス | F14: 住居 | G14: 論理区画 | H14: あり | J14: メゾン雑司ヶ谷 | K14: 869880 | L14: 52092 | M14: 107712 | O14: 20610 | P14: 22836 | U14: 1073130 | W14: コアプラス池袋 | X14: 16087719 | Y14: 78084258 | AA14: 94171977 | AC14: プラウD目白301号室 | AI14: メゾン雑司ヶ谷 | AJ14: 84480 | AK14: 4315064 | AL14: 212477 | AP14: 4612021 | AR14: コアプラスレジデンス梅田 | AT14: 0 | BB14: 0 | BF14: ビジネス新大阪123号 | BI14: 0 | BP14: 0 | BT14: コアプラス池袋 | BV14: 132000 | BX14: 367000 | CA14: 169400 | CB14: 668400 | CF14: 駐車場 | CG14: 809021 | CH14: 794721 | CJ14: レジデンス目白豊島 | CK14: 1239741 | CL14: 1261741 | CM14: 1274740 | CO14: 77 | CP14: 305800 | CQ14: 7 | CS14: 7 | CT14: =VLOOKUP($CO14,chinryo_list,2,FALSE) -> 103 | CU14: =VLOOKUP($CO14,chinryo_list,3,FALSE) -> カーサ目白台ハウス | CV14: =VLOOKUP($CO14,chinryo_list,4,FALSE) -> 503 | CW14: =VLOOKUP($CO14,chinryo_list,7,FALSE) -> 住居 | CX14: =VLOOKUP($CO14,chinryo_list,8,FALSE) -> 2LDK | CY14: =VLOOKUP($CO14,chinryo_list,17,FALSE) -> 305800 | DB14: 40000-49999 | DF14: 住居 | DJ14: ビジネス新大阪123号 | DK14: 19.9 | DL14: 892339.76 | DM14: 1761 | DN14: 754 | DS14: 19.9 | DT14: 892339.76 | DU14: 1761 | DV14: 754 | DY14: ビジネス新大阪123号 | DZ14: 1 | EE14: 1 | EG14: 西池袋駅前ビル | EH14: 712666 | EI14: 139065 | EJ14: 851731 | EK14: 166166517 | EM14: コアプラス大塚 | ES14: 7 | ET14: AG | EU14: AE | EV14: 8 | EW14: {=INDIRECT("'5借入一覧'!"&ET14&EV14)&INDIRECT("'5借入一覧'!"&EU14&EV14)} | EX14: 1 | EY14: 7 | EZ14: =VLOOKUP($EY14&EZ$5,$EW$7:$EX$1101,2,FALSE) -> #N/A | FA14: =VLOOKUP($EY14&FA$5,$EW$7:$EX$1101,2,FALSE) -> #N/A | FB14: =VLOOKUP($EY14&FB$5,$EW$7:$EX$1101,2,FALSE) -> #N/A | FC14: =VLOOKUP($EY14&FC$5,$EW$7:$EX$1101,2,FALSE) -> #N/A | FD14: =VLOOKUP($EY14&FD$5,$EW$7:$EX$1101,2,FALSE) -> #N/A | FE14: =IFERROR(IF(EZ14>0,EZ$7),"") | FF14: =IFERROR(IF(FA14>0,FA$7),"") | FG14: =IFERROR(IF(FB14>0,FB$7),"") | FH14: =IFERROR(IF(FC14>0,FC$7),"") | FI14: =IFERROR(IF(FD14>0,FD$7),"") | FJ14: =FE14&FF14&FG14&FH14&FI14 | FK14: =IF(FJ14<>"",LEFT(FJ14,LEN(FJ14)-1),"") | FL14: =IF(FK14<>"",FK14&"として提供中","無") -> 無 | FN14: 住宅ローン | FO14: 94000000
A15: Pivot13 | B15: =HYPERLINK("#pivot!"&ADDRESS(1,MATCH(A15,$A$1:$GE$1,0),4),A15) -> Pivot13 | C15: 8賃料集計 | D15: 事務所・店舗系_賃貸用資産（非賃貸を除く）の賃料帯別ヒストグラム | E15: クラス | F15: 住居以外複数 | G15: 論理区画 | H15: あり | J15: レジデンス目白豊島 | K15: 405240 | L15: 39024 | M15: 46992 | O15: 7710 | U15: 498966 | W15: ビジネス新大阪123号 | X15: 3052637 | Y15: 2488575 | AA15: 5541212 | AC15: メゾン雑司ヶ谷 | AD15: 73661130 | AE15: 286363375 | AG15: 360024505 | AI15: レジデンス目白豊島 | AK15: 2114406 | AP15: 2114406 | AR15: コアプラス大塚 | AT15: 0 | BB15: 0 | BF15: プラウD目白301号室 | BT15: ビジネス新大阪123号 | BV15: 0 | CB15: 0 | CF15: 店舗 | CG15: 2337093 | CH15: 2337093 | CJ15: 高田馬場第4玉川ビル | CK15: 844300 | CL15: 859000 | CM15: 852000 | CO15: 23 | CP15: 302500 | CQ15: 8 | CS15: 8 | CT15: =VLOOKUP($CO15,chinryo_list,2,FALSE) -> 101 | CU15: =VLOOKUP($CO15,chinryo_list,3,FALSE) -> 西池袋駅前ビル | CV15: =VLOOKUP($CO15,chinryo_list,4,FALSE) -> 100 | CW15: =VLOOKUP($CO15,chinryo_list,7,FALSE) -> 事務所 | CX15: =VLOOKUP($CO15,chinryo_list,8,FALSE) -> 事務所 | CY15: =VLOOKUP($CO15,chinryo_list,17,FALSE) -> 302500 | DB15: 50000-59999 | DC15: 10 | DD15: 564700 | DF15: 倉庫 | DJ15: プラウD目白301号室 | DY15: プラウD目白301号室 | EG15: 仙台駅前コーポ | EM15: コアプラス池袋 | ES15: 8 | ET15: AG | EU15: AE | EV15: 9 | EW15: {=INDIRECT("'5借入一覧'!"&ET15&EV15)&INDIRECT("'5借入一覧'!"&EU15&EV15)} | EX15: 1 | EY15: 8 | EZ15: =VLOOKUP($EY15&EZ$5,$EW$7:$EX$1101,2,FALSE) -> #N/A | FA15: =VLOOKUP($EY15&FA$5,$EW$7:$EX$1101,2,FALSE) -> #N/A | FB15: =VLOOKUP($EY15&FB$5,$EW$7:$EX$1101,2,FALSE) -> #N/A | FC15: =VLOOKUP($EY15&FC$5,$EW$7:$EX$1101,2,FALSE) -> #N/A | FD15: =VLOOKUP($EY15&FD$5,$EW$7:$EX$1101,2,FALSE) -> #N/A | FE15: =IFERROR(IF(EZ15>0,EZ$7),"") | FF15: =IFERROR(IF(FA15>0,FA$7),"") | FG15: =IFERROR(IF(FB15>0,FB$7),"") | FH15: =IFERROR(IF(FC15>0,FC$7),"") | FI15: =IFERROR(IF(FD15>0,FD$7),"") | FJ15: =FE15&FF15&FG15&FH15&FI15 | FK15: =IF(FJ15<>"",LEFT(FJ15,LEN(FJ15)-1),"") | FL15: =IF(FK15<>"",FK15&"として提供中","無") -> 無 | FN15: プラウD目白301号 | FO15: 94000000
A16: Pivot14 | B16: =HYPERLINK("#pivot!"&ADDRESS(1,MATCH(A16,$A$1:$GE$1,0),4),A16) -> Pivot14 | C16: B筆一覧 | D16: 土地建物 筆の一覧 固定資産税評価額/固定資産税/都市計画税額 | J16: 高田馬場第4玉川ビル | K16: 231000 | L16: 9156 | O16: 21200 | T16: -6000 | U16: 255356 | W16: プラウD目白301号室 | AC16: レジデンス目白豊島 | AD16: 42782673 | AE16: 154821009 | AG16: 197603682 | AI16: 高田馬場第4玉川ビル | AK16: 2704931 | AL16: 246267 | AP16: 2951198 | AR16: コアプラス池袋 | BF16: メゾン雑司ヶ谷 | BH16: 0 | BK16: 1378700 | BN16: 1100000 | BP16: 2478700 | BT16: メゾン雑司ヶ谷 | BX16: 1378700 | CA16: 1100000 | CB16: 2478700 | CF16: (空白) | CJ16: 西池袋駅前ビル | CK16: 1691000 | CL16: 1802800 | CM16: 1851800 | CO16: 316 | CP16: 295000 | CQ16: 9 | CS16: 9 | CT16: =VLOOKUP($CO16,chinryo_list,2,FALSE) -> 222 | CU16: =VLOOKUP($CO16,chinryo_list,3,FALSE) -> プラウD目白301号 | CV16: =VLOOKUP($CO16,chinryo_list,4,FALSE) -> 201 | CW16: =VLOOKUP($CO16,chinryo_list,7,FALSE) -> 住居 | CX16: =VLOOKUP($CO16,chinryo_list,8,FALSE) -> 2LDK | CY16: =VLOOKUP($CO16,chinryo_list,17,FALSE) -> 295000 | DB16: 60000-69999 | DC16: 49 | DD16: 3160800 | DF16: 駐車場 | DJ16: メゾン雑司ヶ谷 | DK16: 961.19 | DL16: 49095000 | DM16: 687330 | DN16: 147285 | DO16: 560.83 | DP16: 174332250 | DQ16: 371288 | DR16: 79561 | DS16: 1522.02 | DT16: 223427250 | DU16: 1058618 | DV16: 226846 | DY16: メゾン雑司ヶ谷 | DZ16: 1 | EB16: 22 | EE16: 23 | EG16: 対象物件なし(運転資金) | EH16: 168922 | EI16: 32278 | EJ16: 201200 | EK16: 22489146 | EM16: メゾン雑司ヶ谷 | ES16: 9 | ET16: AG | EU16: AE | EV16: 10 | EW16: {=INDIRECT("'5借入一覧'!"&ET16&EV16)&INDIRECT("'5借入一覧'!"&EU16&EV16)} | EX16: 1 | EY16: 9 | EZ16: =VLOOKUP($EY16&EZ$5,$EW$7:$EX$1101,2,FALSE) -> #N/A | FA16: =VLOOKUP($EY16&FA$5,$EW$7:$EX$1101,2,FALSE) -> #N/A | FB16: =VLOOKUP($EY16&FB$5,$EW$7:$EX$1101,2,FALSE) -> #N/A | FC16: =VLOOKUP($EY16&FC$5,$EW$7:$EX$1101,2,FALSE) -> #N/A | FD16: =VLOOKUP($EY16&FD$5,$EW$7:$EX$1101,2,FALSE) -> #N/A | FE16: =IFERROR(IF(EZ16>0,EZ$7),"") | FF16: =IFERROR(IF(FA16>0,FA$7),"") | FG16: =IFERROR(IF(FB16>0,FB$7),"") | FH16: =IFERROR(IF(FC16>0,FC$7),"") | FI16: =IFERROR(IF(FD16>0,FD$7),"") | FJ16: =FE16&FF16&FG16&FH16&FI16 | FK16: =IF(FJ16<>"",LEFT(FJ16,LEN(FJ16)-1),"") | FL16: =IF(FK16<>"",FK16&"として提供中","無") -> 無 | FN16: 親族借入 | FO16: 2000000
A17: Pivot15 | B17: =HYPERLINK("#pivot!"&ADDRESS(1,MATCH(A17,$A$1:$GE$1,0),4),A17) -> Pivot15 | C17: 3物件一覧 | D17: C24総区画数 | G17: 論理区画 | H17: あり | J17: 西池袋駅前ビル | K17: 596640 | L17: 251892 | N17: 144564 | O17: 11830 | P17: 18744 | U17: 1023670 | W17: メゾン雑司ヶ谷 | X17: 98069650 | Y17: 286363375 | AA17: 384433025 | AC17: 高田馬場第4玉川ビル | AD17: 15377543 | AE17: 113543242 | AG17: 128920785 | AI17: 西池袋駅前ビル | AJ17: 114456 | AK17: 1867320 | AL17: 49313 | AP17: 2031089 | AR17: ビジネス新大阪123号 | BF17: レジデンス目白豊島 | BI17: 94600 | BK17: 935000 | BL17: 264815 | BP17: 1294415 | BT17: レジデンス目白豊島 | BV17: 94600 | BX17: 935000 | BY17: 264815 | CB17: 1294415 | CF17: 総計 | CG17: 35648978 | CH17: 35307474 | CJ17: 第3目白ハイツ | CK17: 2897000 | CL17: 3004000 | CM17: 2948000 | CO17: 250 | CP17: 264815 | CQ17: 10 | CS17: 10 | CT17: =VLOOKUP($CO17,chinryo_list,2,FALSE) -> 114 | CU17: =VLOOKUP($CO17,chinryo_list,3,FALSE) -> レジデンス目白豊島 | CV17: =VLOOKUP($CO17,chinryo_list,4,FALSE) -> 101 | CW17: =VLOOKUP($CO17,chinryo_list,7,FALSE) -> 倉庫 | CX17: =VLOOKUP($CO17,chinryo_list,8,FALSE) -> 倉庫 | CY17: =VLOOKUP($CO17,chinryo_list,17,FALSE) -> 264815 | DB17: 70000-79999 | DC17: 22 | DD17: 1623000 | DF17: 店舗 | DJ17: レジデンス目白豊島 | DK17: 364.28 | DL17: 330468800 | DM17: 289150 | DN17: 61958 | DO17: 191.86 | DP17: 75806570 | DQ17: 148426 | DR17: 31805 | DS17: 556.14 | DT17: 406275370 | DU17: 437576 | DV17: 93763 | DY17: レジデンス目白豊島 | DZ17: 1 | EB17: 14 | EC17: 1 | EE17: 16 | EG17: 第3目白ハイツ | EH17: 1209934 | EI17: 468878 | EJ17: 1678812 | EK17: 407992887 | EM17: レジデンス目白豊島 | ES17: 10 | ET17: AG | EU17: AE | EV17: 11 | EW17: {=INDIRECT("'5借入一覧'!"&ET17&EV17)&INDIRECT("'5借入一覧'!"&EU17&EV17)} | EX17: 1 | EY17: 10 | EZ17: =VLOOKUP($EY17&EZ$5,$EW$7:$EX$1101,2,FALSE) -> #N/A | FA17: =VLOOKUP($EY17&FA$5,$EW$7:$EX$1101,2,FALSE) -> #N/A | FB17: =VLOOKUP($EY17&FB$5,$EW$7:$EX$1101,2,FALSE) -> #N/A | FC17: =VLOOKUP($EY17&FC$5,$EW$7:$EX$1101,2,FALSE) -> #N/A | FD17: =VLOOKUP($EY17&FD$5,$EW$7:$EX$1101,2,FALSE) -> #N/A | FE17: =IFERROR(IF(EZ17>0,EZ$7),"") | FF17: =IFERROR(IF(FA17>0,FA$7),"") | FG17: =IFERROR(IF(FB17>0,FB$7),"") | FH17: =IFERROR(IF(FC17>0,FC$7),"") | FI17: =IFERROR(IF(FD17>0,FD$7),"") | FJ17: =FE17&FF17&FG17&FH17&FI17 | FK17: =IF(FJ17<>"",LEFT(FJ17,LEN(FJ17)-1),"") | FL17: =IF(FK17<>"",FK17&"として提供中","無") -> 無 | FN17: 対象物件なし(運転資金) | FO17: 2000000
A18: Pivot16 | B18: =HYPERLINK("#pivot!"&ADDRESS(1,MATCH(A18,$A$1:$GE$1,0),4),A18) -> Pivot16 | C18: 3物件一覧 | D18: ="C41"&'3物件一覧'!B34 -> C41残債2022年11月5日現在 | J18: 第3目白ハイツ | K18: 848760 | L18: 91716 | M18: 282516 | O18: 51350 | P18: 45672 | U18: 1320014 | W18: レジデンス目白豊島 | X18: 52665555 | Y18: 154821009 | AA18: 207486564 | AC18: 西池袋駅前ビル | AD18: 40681559 | AE18: 168935000 | AG18: 209616559 | AI18: 第3目白ハイツ | AK18: 6299558 | AL18: 744405 | AM18: 151956 | AP18: 7195919 | AR18: メゾン雑司ヶ谷 | AT18: 0 | BB18: 0 | BF18: 高田馬場第4玉川ビル | BK18: 846000 | BM18: 0 | BP18: 846000 | BT18: 高田馬場第4玉川ビル | BX18: 846000 | BZ18: 0 | CB18: 846000 | CJ18: 池袋ハウス | CK18: 2801000 | CL18: 3092000 | CM18: 3109000 | CO18: 71 | CP18: 220000 | CQ18: 11 | CS18: 11 | CT18: =VLOOKUP($CO18,chinryo_list,2,FALSE) -> 103 | CU18: =VLOOKUP($CO18,chinryo_list,3,FALSE) -> カーサ目白台ハウス | CV18: =VLOOKUP($CO18,chinryo_list,4,FALSE) -> 303 | CW18: =VLOOKUP($CO18,chinryo_list,7,FALSE) -> 住居 | CX18: =VLOOKUP($CO18,chinryo_list,8,FALSE) -> 2LDK | CY18: =VLOOKUP($CO18,chinryo_list,17,FALSE) -> 220000 | DB18: 80000-89999 | DC18: 26 | DD18: 2172000 | DF18: (空白) | DJ18: 高田馬場第4玉川ビル | DK18: 343.46 | DL18: 10120600 | DM18: 141688 | DN18: 30361 | DO18: 179.23 | DP18: 75126040 | DQ18: 144698 | DR18: 31006 | DS18: 522.69 | DT18: 85246640 | DU18: 286386 | DV18: 61367 | DY18: 高田馬場第4玉川ビル | EB18: 8 | ED18: 1 | EE18: 9 | EG18: 池袋ハウス | EH18: 1050252 | EI18: 674466 | EJ18: 1724718 | EK18: 489470974 | EM18: 高田馬場第4玉川ビル | ES18: 11 | ET18: AG | EU18: AE | EV18: 12 | EW18: {=INDIRECT("'5借入一覧'!"&ET18&EV18)&INDIRECT("'5借入一覧'!"&EU18&EV18)} | EX18: 1 | EY18: 11 | EZ18: =VLOOKUP($EY18&EZ$5,$EW$7:$EX$1101,2,FALSE) -> #N/A | FA18: =VLOOKUP($EY18&FA$5,$EW$7:$EX$1101,2,FALSE) -> #N/A | FB18: =VLOOKUP($EY18&FB$5,$EW$7:$EX$1101,2,FALSE) -> #N/A | FC18: =VLOOKUP($EY18&FC$5,$EW$7:$EX$1101,2,FALSE) -> #N/A | FD18: =VLOOKUP($EY18&FD$5,$EW$7:$EX$1101,2,FALSE) -> #N/A | FE18: =IFERROR(IF(EZ18>0,EZ$7),"") | FF18: =IFERROR(IF(FA18>0,FA$7),"") | FG18: =IFERROR(IF(FB18>0,FB$7),"") | FH18: =IFERROR(IF(FC18>0,FC$7),"") | FI18: =IFERROR(IF(FD18>0,FD$7),"") | FJ18: =FE18&FF18&FG18&FH18&FI18 | FK18: =IF(FJ18<>"",LEFT(FJ18,LEN(FJ18)-1),"") | FL18: =IF(FK18<>"",FK18&"として提供中","無") -> 無 | FN18: 他業借入 | FO18: 11000000
A19: Pivot17 | B19: =HYPERLINK("#pivot!"&ADDRESS(1,MATCH(A19,$A$1:$GE$1,0),4),A19) -> Pivot17 | C19: 2法人連結 | D19: グループ全体P/L | J19: 池袋ハウス | K19: 1708080 | L19: 382320 | M19: 273012 | N19: 132000 | O19: 44050 | P19: 45672 | U19: 2585134 | W19: 高田馬場第4玉川ビル | X19: 24151178 | Y19: 113543242 | AA19: 137694420 | AC19: 第3目白ハイツ | AD19: 127400532 | AE19: 335018465 | AG19: 462418997 | AI19: 池袋ハウス | AK19: 6519475 | AL19: 302954 | AP19: 6822429 | AR19: レジデンス目白豊島 | BF19: 西池袋駅前ビル | BG19: 99000 | BH19: 0 | BI19: 302500 | BK19: 1437800 | BP19: 1839300 | BT19: 西池袋駅前ビル | BU19: 99000 | BV19: 302500 | BX19: 1437800 | CB19: 1839300 | CJ19: 東池袋ハイツ | CK19: 2820000 | CL19: 3096000 | CM19: 3072000 | CO19: 75 | CP19: 218000 | CQ19: 12 | CS19: 12 | CT19: =VLOOKUP($CO19,chinryo_list,2,FALSE) -> 103 | CU19: =VLOOKUP($CO19,chinryo_list,3,FALSE) -> カーサ目白台ハウス | CV19: =VLOOKUP($CO19,chinryo_list,4,FALSE) -> 501 | CW19: =VLOOKUP($CO19,chinryo_list,7,FALSE) -> 住居 | CX19: =VLOOKUP($CO19,chinryo_list,8,FALSE) -> 2LDK | CY19: =VLOOKUP($CO19,chinryo_list,17,FALSE) -> 218000 | DB19: 90000-99999 | DC19: 10 | DD19: 941612 | DF19: 0-99999 | DG19: 26 | DH19: 1040061 | DJ19: 西池袋駅前ビル | DK19: 528.43 | DL19: 33429500 | DM19: 468013 | DN19: 100288 | DO19: 313.11 | DP19: 130723720 | DQ19: 270901 | DR19: 58050 | DS19: 841.54 | DT19: 164153220 | DU19: 738914 | DV19: 158338 | DY19: 西池袋駅前ビル | DZ19: 1 | EA19: 1 | EB19: 22 | EE19: 24 | EG19: 東池袋ハイツ | EH19: 970634 | EI19: 241754 | EJ19: 1212388 | EK19: 289146337 | EM19: 西池袋駅前ビル | ES19: 12 | ET19: AG | EU19: AE | EV19: 13 | EW19: {=INDIRECT("'5借入一覧'!"&ET19&EV19)&INDIRECT("'5借入一覧'!"&EU19&EV19)} | EX19: 1 | EY19: 12 | EZ19: =VLOOKUP($EY19&EZ$5,$EW$7:$EX$1101,2,FALSE) -> #N/A | FA19: =VLOOKUP($EY19&FA$5,$EW$7:$EX$1101,2,FALSE) -> #N/A | FB19: =VLOOKUP($EY19&FB$5,$EW$7:$EX$1101,2,FALSE) -> #N/A | FC19: =VLOOKUP($EY19&FC$5,$EW$7:$EX$1101,2,FALSE) -> #N/A | FD19: =VLOOKUP($EY19&FD$5,$EW$7:$EX$1101,2,FALSE) -> #N/A | FE19: =IFERROR(IF(EZ19>0,EZ$7),"") | FF19: =IFERROR(IF(FA19>0,FA$7),"") | FG19: =IFERROR(IF(FB19>0,FB$7),"") | FH19: =IFERROR(IF(FC19>0,FC$7),"") | FI19: =IFERROR(IF(FD19>0,FD$7),"") | FJ19: =FE19&FF19&FG19&FH19&FI19 | FK19: =IF(FJ19<>"",LEFT(FJ19,LEN(FJ19)-1),"") | FL19: =IF(FK19<>"",FK19&"として提供中","無") -> 無 | FN19: 対象物件なし(運転資金) | FO19: 11000000
A20: Pivot18 | B20: =HYPERLINK("#pivot!"&ADDRESS(1,MATCH(A20,$A$1:$GE$1,0),4),A20) -> Pivot18 | C20: 3物件一覧 | D20: 共同担保の提供状況 | J20: 東池袋ハイツ | K20: 1801800 | L20: 277608 | M20: 164676 | O20: 45780 | P20: 18744 | U20: 2308608 | W20: 西池袋駅前ビル | X20: 51870000 | Y20: 168935000 | AA20: 220805000 | AC20: 池袋ハウス | AD20: 131180095 | AE20: 400269597 | AG20: 531449692 | AI20: 東池袋ハイツ | AJ20: 62964 | AK20: 6359913 | AP20: 6422877 | AR20: 高田馬場第4玉川ビル | BF20: 第3目白ハイツ | BH20: 0 | BK20: 2984000 | BM20: 22000 | BP20: 3006000 | BT20: 第3目白ハイツ | BX20: 2984000 | BZ20: 22000 | CB20: 3006000 | CJ20: 南池袋マンション | CK20: 894000 | CL20: 868000 | CM20: 866000 | CO20: 69 | CP20: 218000 | CQ20: 12 | CS20: 13 | CT20: =VLOOKUP($CO20,chinryo_list,2,FALSE) -> 103 | CU20: =VLOOKUP($CO20,chinryo_list,3,FALSE) -> カーサ目白台ハウス | CV20: =VLOOKUP($CO20,chinryo_list,4,FALSE) -> 301 | CW20: =VLOOKUP($CO20,chinryo_list,7,FALSE) -> 住居 | CX20: =VLOOKUP($CO20,chinryo_list,8,FALSE) -> 2LDK | CY20: =VLOOKUP($CO20,chinryo_list,17,FALSE) -> 218000 | DB20: 100000-109999 | DC20: 13 | DD20: 1346853 | DF20: アンテナ | DG20: 8 | DH20: 247035 | DJ20: 第3目白ハイツ | DK20: 1307.01 | DL20: 63199800 | DM20: 884796 | DN20: 189598 | DO20: 805.94 | DP20: 180415820 | DQ20: 377500 | DR20: 80892 | DS20: 2112.95 | DT20: 243615620 | DU20: 1262296 | DV20: 270490 | DY20: 第3目白ハイツ | EB20: 24 | ED20: 1 | EE20: 25 | EG20: 南池袋マンション | EH20: 294357 | EI20: 191699 | EJ20: 486056 | EK20: 139123336 | EM20: 仙台駅前コーポ | ES20: 13 | ET20: AG | EU20: AE | EV20: 14 | EW20: {=INDIRECT("'5借入一覧'!"&ET20&EV20)&INDIRECT("'5借入一覧'!"&EU20&EV20)} | EX20: 1 | EY20: 13 | EZ20: =VLOOKUP($EY20&EZ$5,$EW$7:$EX$1101,2,FALSE) -> #N/A | FA20: =VLOOKUP($EY20&FA$5,$EW$7:$EX$1101,2,FALSE) -> #N/A | FB20: =VLOOKUP($EY20&FB$5,$EW$7:$EX$1101,2,FALSE) -> #N/A | FC20: =VLOOKUP($EY20&FC$5,$EW$7:$EX$1101,2,FALSE) -> #N/A | FD20: =VLOOKUP($EY20&FD$5,$EW$7:$EX$1101,2,FALSE) -> #N/A | FE20: =IFERROR(IF(EZ20>0,EZ$7),"") | FF20: =IFERROR(IF(FA20>0,FA$7),"") | FG20: =IFERROR(IF(FB20>0,FB$7),"") | FH20: =IFERROR(IF(FC20>0,FC$7),"") | FI20: =IFERROR(IF(FD20>0,FD$7),"") | FJ20: =FE20&FF20&FG20&FH20&FI20 | FK20: =IF(FJ20<>"",LEFT(FJ20,LEN(FJ20)-1),"") | FL20: =IF(FK20<>"",FK20&"として提供中","無") -> 無 | FN20: 不動産購入 | FO20: 5170500000
A21: Pivot19 | B21: =HYPERLINK("#pivot!"&ADDRESS(1,MATCH(A21,$A$1:$GE$1,0),4),A21) -> Pivot19 | C21: 8賃料集計 | D21: 現況賃料(税込・月額) | E21: 賃貸用 | F21: yesのみ | G21: 論理区画 | H21: あり | J21: 南池袋マンション | K21: 303600 | L21: 121512 | M21: 43704 | N21: 15840 | O21: 13630 | P21: 18744 | U21: 517030 | W21: 第3目白ハイツ | X21: 149989486 | Y21: 335018465 | AA21: 485007951 | AC21: 東池袋ハイツ | AD21: 142832573 | AE21: 262709157 | AG21: 405541730 | AI21: 南池袋マンション | AK21: 1410700 | AL21: 227130 | AP21: 1637830 | AR21: 西池袋駅前ビル | AT21: 0 | BB21: 0 | BF21: 池袋ハウス | BH21: 0 | BK21: 3026000 | BM21: 72000 | BP21: 3098000 | BT21: 池袋ハウス | BX21: 3026000 | BZ21: 72000 | CB21: 3098000 | CJ21: 豊島目白ビル | CK21: 2500000 | CL21: 2300000 | CM21: 2300000 | CO21: 72 | CP21: 208000 | CQ21: 13 | CS21: 14 | CT21: =VLOOKUP($CO21,chinryo_list,2,FALSE) -> 103 | CU21: =VLOOKUP($CO21,chinryo_list,3,FALSE) -> カーサ目白台ハウス | CV21: =VLOOKUP($CO21,chinryo_list,4,FALSE) -> 401 | CW21: =VLOOKUP($CO21,chinryo_list,7,FALSE) -> 住居 | CX21: =VLOOKUP($CO21,chinryo_list,8,FALSE) -> 2LDK | CY21: =VLOOKUP($CO21,chinryo_list,17,FALSE) -> 208000 | DB21: 110000-119999 | DC21: 12 | DD21: 1370037 | DF21: その他 | DJ21: 池袋ハウス | DK21: 1110.34 | DL21: 75934400 | DM21: 1063081 | DN21: 227803 | DO21: 732.25 | DP21: 263268590 | DQ21: 520012 | DR21: 111430 | DS21: 1842.59 | DT21: 339202990 | DU21: 1583093 | DV21: 339233 | DY21: 池袋ハウス | EB21: 34 | ED21: 2 | EE21: 36 | EG21: 豊島目白ビル | EH21: 1111644 | EI21: 398578 | EJ21: 1510222 | EK21: 366807279 | EM21: 対象物件なし(運転資金) | ES21: 14 | ET21: AG | EU21: AE | EV21: 15 | EW21: {=INDIRECT("'5借入一覧'!"&ET21&EV21)&INDIRECT("'5借入一覧'!"&EU21&EV21)} | EX21: 1 | EY21: 14 | EZ21: =VLOOKUP($EY21&EZ$5,$EW$7:$EX$1101,2,FALSE) -> #N/A | FA21: =VLOOKUP($EY21&FA$5,$EW$7:$EX$1101,2,FALSE) -> #N/A | FB21: =VLOOKUP($EY21&FB$5,$EW$7:$EX$1101,2,FALSE) -> #N/A | FC21: =VLOOKUP($EY21&FC$5,$EW$7:$EX$1101,2,FALSE) -> #N/A | FD21: =VLOOKUP($EY21&FD$5,$EW$7:$EX$1101,2,FALSE) -> #N/A | FE21: =IFERROR(IF(EZ21>0,EZ$7),"") | FF21: =IFERROR(IF(FA21>0,FA$7),"") | FG21: =IFERROR(IF(FB21>0,FB$7),"") | FH21: =IFERROR(IF(FC21>0,FC$7),"") | FI21: =IFERROR(IF(FD21>0,FD$7),"") | FJ21: =FE21&FF21&FG21&FH21&FI21 | FK21: =IF(FJ21<>"",LEFT(FJ21,LEN(FJ21)-1),"") | FL21: =IF(FK21<>"",FK21&"として提供中","無") -> 無 | FN21: カーサ南池袋 | FO21: 180000000
A22: Pivot20 | B22: =HYPERLINK("#pivot!"&ADDRESS(1,MATCH(A22,$A$1:$GE$1,0),4),A22) -> Pivot20 | C22: 5借入一覧 | D22: 不動産当初借入額、返済中のみ | J22: 豊島目白ビル | K22: 659419 | O22: 10340 | U22: 669759 | W22: 池袋ハウス | X22: 155225603 | Y22: 400269597 | AA22: 555495200 | AC22: 南池袋マンション | AD22: 30483564 | AE22: 120828203 | AG22: 151311767 | AI22: 豊島目白ビル | AK22: 4817807 | AP22: 4817807 | AR22: 第3目白ハイツ | AT22: 0 | BB22: 0 | BF22: 東池袋ハイツ | BG22: 13200 | BH22: 0 | BK22: 3084000 | BP22: 3097200 | BT22: 東池袋ハイツ | BU22: 13200 | BX22: 3084000 | CB22: 3097200 | CJ22: 目白アパート | CK22: 2602124 | CL22: 2783347 | CM22: 2804220 | CO22: 70 | CP22: 208000 | CQ22: 13 | CS22: 15 | CT22: =VLOOKUP($CO22,chinryo_list,2,FALSE) -> 103 | CU22: =VLOOKUP($CO22,chinryo_list,3,FALSE) -> カーサ目白台ハウス | CV22: =VLOOKUP($CO22,chinryo_list,4,FALSE) -> 302 | CW22: =VLOOKUP($CO22,chinryo_list,7,FALSE) -> 住居 | CX22: =VLOOKUP($CO22,chinryo_list,8,FALSE) -> 2DK | CY22: =VLOOKUP($CO22,chinryo_list,17,FALSE) -> 208000 | DB22: 120000-129999 | DC22: 23 | DD22: 2874000 | DF22: 事務所 | DG22: 3 | DH22: 223886 | DJ22: 東池袋ハイツ | DK22: 1133.51 | DL22: 77454600 | DM22: 1084364 | DN22: 232363 | DO22: 286.9 | DP22: 149184550 | DQ22: 287722 | DR22: 61654 | DS22: 1420.41 | DT22: 226639150 | DU22: 1372086 | DV22: 294017 | DY22: 東池袋ハイツ | EA22: 1 | EB22: 21 | EE22: 22 | EG22: 目白アパート | EH22: 995627 | EI22: 166971 | EJ22: 1162598 | EK22: 199606609 | EM22: 第3目白ハイツ | ES22: 15 | ET22: AG | EU22: AE | EV22: 16 | EW22: {=INDIRECT("'5借入一覧'!"&ET22&EV22)&INDIRECT("'5借入一覧'!"&EU22&EV22)} | EX22: 1 | EY22: 15 | EZ22: =VLOOKUP($EY22&EZ$5,$EW$7:$EX$1101,2,FALSE) -> #N/A | FA22: =VLOOKUP($EY22&FA$5,$EW$7:$EX$1101,2,FALSE) -> #N/A | FB22: =VLOOKUP($EY22&FB$5,$EW$7:$EX$1101,2,FALSE) -> #N/A | FC22: =VLOOKUP($EY22&FC$5,$EW$7:$EX$1101,2,FALSE) -> #N/A | FD22: =VLOOKUP($EY22&FD$5,$EW$7:$EX$1101,2,FALSE) -> #N/A | FE22: =IFERROR(IF(EZ22>0,EZ$7),"") | FF22: =IFERROR(IF(FA22>0,FA$7),"") | FG22: =IFERROR(IF(FB22>0,FB$7),"") | FH22: =IFERROR(IF(FC22>0,FC$7),"") | FI22: =IFERROR(IF(FD22>0,FD$7),"") | FJ22: =FE22&FF22&FG22&FH22&FI22 | FK22: =IF(FJ22<>"",LEFT(FJ22,LEN(FJ22)-1),"") | FL22: =IF(FK22<>"",FK22&"として提供中","無") -> 無 | FN22: カーサ目白台ハウス | FO22: 413500000
J23: 目白アパート | K23: 1157640 | L23: 217104 | M23: 162288 | O23: 20710 | P23: 22836 | U23: 1580578 | W23: 賃貸資産以外の償却 | X23: 3756438 | AA23: 3756438 | AC23: 豊島目白ビル | AD23: 98680532 | AE23: 316421235 | AG23: 415101767 | AI23: 目白アパート | AK23: 8734332 | AL23: 1646415 | AM23: 80146 | AP23: 10460893 | AR23: 池袋ハウス | AT23: 0 | BB23: 0 | BF23: 南池袋マンション | BH23: 0 | BJ23: 0 | BK23: 868000 | BP23: 868000 | BT23: 南池袋マンション | BW23: 0 | BX23: 868000 | CB23: 868000 | CJ23: 目白カーサ二番館 | CK23: 1863350 | CL23: 1862034 | CM23: 1856107 | CO23: 76 | CP23: 198000 | CQ23: 14 | CS23: 16 | CT23: =VLOOKUP($CO23,chinryo_list,2,FALSE) -> 103 | CU23: =VLOOKUP($CO23,chinryo_list,3,FALSE) -> カーサ目白台ハウス | CV23: =VLOOKUP($CO23,chinryo_list,4,FALSE) -> 502 | CW23: =VLOOKUP($CO23,chinryo_list,7,FALSE) -> 住居 | CX23: =VLOOKUP($CO23,chinryo_list,8,FALSE) -> 1LDK | CY23: =VLOOKUP($CO23,chinryo_list,17,FALSE) -> 198000 | DB23: 130000-139999 | DC23: 32 | DD23: 4269000 | DF23: 自販機 | DG23: 1 | DH23: 0 | DJ23: 南池袋マンション | DK23: 349.27 | DL23: 18910900 | DM23: 264752 | DN23: 56732 | DO23: 306.83 | DP23: 79056190 | DQ23: 167336 | DR23: 35857 | DS23: 656.1 | DT23: 97967090 | DU23: 432088 | DV23: 92589 | DY23: 南池袋マンション | EB23: 9 | EE23: 9 | EG23: 目白カーサ二番館 | EH23: 692442 | EI23: 247247 | EJ23: 939689 | EK23: 227542871 | EM23: 池袋ハウス | ES23: 16 | ET23: AG | EU23: AE | EV23: 17 | EW23: {=INDIRECT("'5借入一覧'!"&ET23&EV23)&INDIRECT("'5借入一覧'!"&EU23&EV23)} | EX23: 1 | EY23: 16 | EZ23: =VLOOKUP($EY23&EZ$5,$EW$7:$EX$1101,2,FALSE) -> #N/A | FA23: =VLOOKUP($EY23&FA$5,$EW$7:$EX$1101,2,FALSE) -> #N/A | FB23: =VLOOKUP($EY23&FB$5,$EW$7:$EX$1101,2,FALSE) -> #N/A | FC23: =VLOOKUP($EY23&FC$5,$EW$7:$EX$1101,2,FALSE) -> #N/A | FD23: =VLOOKUP($EY23&FD$5,$EW$7:$EX$1101,2,FALSE) -> #N/A | FE23: =IFERROR(IF(EZ23>0,EZ$7),"") | FF23: =IFERROR(IF(FA23>0,FA$7),"") | FG23: =IFERROR(IF(FB23>0,FB$7),"") | FH23: =IFERROR(IF(FC23>0,FC$7),"") | FI23: =IFERROR(IF(FD23>0,FD$7),"") | FJ23: =FE23&FF23&FG23&FH23&FI23 | FK23: =IF(FJ23<>"",LEFT(FJ23,LEN(FJ23)-1),"") | FL23: =IF(FK23<>"",FK23&"として提供中","無") -> 無 | FN23: コアプラスレジデンス梅田 | FO23: 369000000
J24: 目白カーサ二番館 | K24: 838200 | L24: 136284 | M24: 245880 | O24: 19920 | P24: 18744 | U24: 1259028 | W24: 東池袋ハイツ | X24: 187056281 | Y24: 262709157 | AA24: 449765438 | AC24: 目白アパート | AD24: 70902303 | AE24: 192559845 | AG24: 263462148 | AI24: 目白カーサ二番館 | AK24: 4300138 | AP24: 4300138 | AR24: 東池袋ハイツ | AT24: 0 | BB24: 0 | BF24: 豊島目白ビル | BI24: 2530000 | BP24: 2530000 | BT24: 豊島目白ビル | BV24: 2530000 | CB24: 2530000 | CJ24: 目白アパート1号館 | CK24: 330000 | CL24: 330000 | CM24: 330000 | CO24: 73 | CP24: 198000 | CQ24: 14 | CS24: 17 | CT24: =VLOOKUP($CO24,chinryo_list,2,FALSE) -> 103 | CU24: =VLOOKUP($CO24,chinryo_list,3,FALSE) -> カーサ目白台ハウス | CV24: =VLOOKUP($CO24,chinryo_list,4,FALSE) -> 402 | CW24: =VLOOKUP($CO24,chinryo_list,7,FALSE) -> 住居 | CX24: =VLOOKUP($CO24,chinryo_list,8,FALSE) -> 2LDK | CY24: =VLOOKUP($CO24,chinryo_list,17,FALSE) -> 198000 | DB24: 140000-149999 | DC24: 8 | DD24: 1143000 | DF24: 倉庫 | DG24: 1 | DH24: 17600 | DJ24: 豊島目白ビル | DK24: 491.32 | DL24: 39293700 | DM24: 0 | DN24: 0 | DO24: 143.13 | DP24: 147431050 | DQ24: 785817 | DR24: 168388 | DS24: 634.45 | DT24: 186724750 | DU24: 785817 | DV24: 168388 | DY24: 豊島目白ビル | DZ24: 1 | EE24: 1 | EG24: (空白) | EM24: 東池袋ハイツ | ES24: 17 | ET24: AG | EU24: AE | EV24: 18 | EW24: {=INDIRECT("'5借入一覧'!"&ET24&EV24)&INDIRECT("'5借入一覧'!"&EU24&EV24)} | EX24: 1 | EY24: 17 | EZ24: =VLOOKUP($EY24&EZ$5,$EW$7:$EX$1101,2,FALSE) -> #N/A | FA24: =VLOOKUP($EY24&FA$5,$EW$7:$EX$1101,2,FALSE) -> #N/A | FB24: =VLOOKUP($EY24&FB$5,$EW$7:$EX$1101,2,FALSE) -> #N/A | FC24: =VLOOKUP($EY24&FC$5,$EW$7:$EX$1101,2,FALSE) -> #N/A | FD24: =VLOOKUP($EY24&FD$5,$EW$7:$EX$1101,2,FALSE) -> #N/A | FE24: =IFERROR(IF(EZ24>0,EZ$7),"") | FF24: =IFERROR(IF(FA24>0,FA$7),"") | FG24: =IFERROR(IF(FB24>0,FB$7),"") | FH24: =IFERROR(IF(FC24>0,FC$7),"") | FI24: =IFERROR(IF(FD24>0,FD$7),"") | FJ24: =FE24&FF24&FG24&FH24&FI24 | FK24: =IF(FJ24<>"",LEFT(FJ24,LEN(FJ24)-1),"") | FL24: =IF(FK24<>"",FK24&"として提供中","無") -> 無 | FN24: コアプラス大塚 | FO24: 530000000
J25: (空白) | W25: 南池袋マンション | X25: 33588101 | Y25: 120828203 | AA25: 154416304 | AC25: 目白カーサ二番館 | AD25: 34281663 | AE25: 252984606 | AG25: 287266269 | AI25: (空白) | AR25: 南池袋マンション | AT25: 0 | BB25: 0 | BF25: 目白アパート | BG25: 35524 | BH25: 0 | BK25: 2385298 | BM25: 77000 | BN25: 99000 | BP25: 2596822 | BT25: 目白アパート | BU25: 35524 | BX25: 2385298 | BZ25: 77000 | CA25: 99000 | CB25: 2596822 | CJ25: 目白アパート2号館 | CK25: 160000 | CL25: 160000 | CM25: 160000 | CO25: 66 | CP25: 198000 | CQ25: 14 | CS25: 18 | CT25: =VLOOKUP($CO25,chinryo_list,2,FALSE) -> 103 | CU25: =VLOOKUP($CO25,chinryo_list,3,FALSE) -> カーサ目白台ハウス | CV25: =VLOOKUP($CO25,chinryo_list,4,FALSE) -> 201 | CW25: =VLOOKUP($CO25,chinryo_list,7,FALSE) -> 店舗 | CX25: =VLOOKUP($CO25,chinryo_list,8,FALSE) -> 事務所 | CY25: =VLOOKUP($CO25,chinryo_list,17,FALSE) -> 198000 | DB25: 150000-159999 | DC25: 11 | DD25: 1673000 | DF25: 駐車場 | DG25: 12 | DH25: 452540 | DJ25: 目白アパート | DK25: 1072.93 | DL25: 42218400 | DM25: 591057 | DN25: 126655 | DO25: 342.64 | DP25: 102949060 | DQ25: 203175 | DR25: 43537 | DS25: 1415.57 | DT25: 145167460 | DU25: 794232 | DV25: 170192 | DY25: 目白アパート | DZ25: 1 | EA25: 2 | EB25: 24 | ED25: 2 | EE25: 29 | EG25: 目白アパート1号館 | EH25: 49298 | EI25: 14364 | EJ25: 63662 | EK25: 9268450 | EM25: 南池袋マンション | ES25: 18 | ET25: AG | EU25: AE | EV25: 19 | EW25: {=INDIRECT("'5借入一覧'!"&ET25&EV25)&INDIRECT("'5借入一覧'!"&EU25&EV25)} | EX25: 1 | EY25: 18 | EZ25: =VLOOKUP($EY25&EZ$5,$EW$7:$EX$1101,2,FALSE) -> #N/A | FA25: =VLOOKUP($EY25&FA$5,$EW$7:$EX$1101,2,FALSE) -> #N/A | FB25: =VLOOKUP($EY25&FB$5,$EW$7:$EX$1101,2,FALSE) -> #N/A | FC25: =VLOOKUP($EY25&FC$5,$EW$7:$EX$1101,2,FALSE) -> #N/A | FD25: =VLOOKUP($EY25&FD$5,$EW$7:$EX$1101,2,FALSE) -> #N/A | FE25: =IFERROR(IF(EZ25>0,EZ$7),"") | FF25: =IFERROR(IF(FA25>0,FA$7),"") | FG25: =IFERROR(IF(FB25>0,FB$7),"") | FH25: =IFERROR(IF(FC25>0,FC$7),"") | FI25: =IFERROR(IF(FD25>0,FD$7),"") | FJ25: =FE25&FF25&FG25&FH25&FI25 | FK25: =IF(FJ25<>"",LEFT(FJ25,LEN(FJ25)-1),"") | FL25: =IF(FK25<>"",FK25&"として提供中","無") -> 無 | FN25: コアプラス池袋 | FO25: 102000000
J26: 目白アパート1号館 | K26: 240000 | U26: 240000 | W26: 豊島目白ビル | X26: 126784406 | Y26: 316421235 | AA26: 443205641 | AC26: (空白) | AI26: 目白アパート1号館 | AK26: 2500000 | AN26: 0 | AP26: 2500000 | AR26: 豊島目白ビル | BF26: 目白カーサ二番館 | BK26: 1758634 | BM26: 113740 | BP26: 1872374 | BT26: 目白アパート1号館 | BX26: 330000 | CB26: 330000 | CJ26: プラウD目白301号 | CK26: 295000 | CL26: 295000 | CM26: 295000 | CO26: 274 | CP26: 192093 | CQ26: 15 | CS26: 19 | CT26: =VLOOKUP($CO26,chinryo_list,2,FALSE) -> 115 | CU26: =VLOOKUP($CO26,chinryo_list,3,FALSE) -> コアプラス大塚 | CV26: =VLOOKUP($CO26,chinryo_list,4,FALSE) -> 101 | CW26: =VLOOKUP($CO26,chinryo_list,7,FALSE) -> 店舗 | CX26: =VLOOKUP($CO26,chinryo_list,8,FALSE) -> 店舗 | CY26: =VLOOKUP($CO26,chinryo_list,17,FALSE) -> 192093 | DB26: 160000-169999 | DC26: 10 | DD26: 1635000 | DF26: 店舗 | DG26: 1 | DH26: 99000 | DJ26: 目白カーサ二番館 | DK26: 496.02 | DL26: 23300500 | DM26: 326207 | DN26: 69901 | DO26: 278.71 | DP26: 136851060 | DQ26: 276361 | DR26: 59220 | DS26: 774.73 | DT26: 160151560 | DU26: 602568 | DV26: 129121 | DY26: 目白カーサ二番館 | EB26: 10 | ED26: 11 | EE26: 21 | EG26: プラウD目白301号 | EH26: 496340 | EI26: 264250 | EJ26: 760590 | EK26: 108163551 | EM26: 豊島目白ビル | ES26: 19 | ET26: AG | EU26: AE | EV26: 20 | EW26: {=INDIRECT("'5借入一覧'!"&ET26&EV26)&INDIRECT("'5借入一覧'!"&EU26&EV26)} | EX26: 1 | EY26: 19 | EZ26: =VLOOKUP($EY26&EZ$5,$EW$7:$EX$1101,2,FALSE) -> #N/A | FA26: =VLOOKUP($EY26&FA$5,$EW$7:$EX$1101,2,FALSE) -> #N/A | FB26: =VLOOKUP($EY26&FB$5,$EW$7:$EX$1101,2,FALSE) -> #N/A | FC26: =VLOOKUP($EY26&FC$5,$EW$7:$EX$1101,2,FALSE) -> #N/A | FD26: =VLOOKUP($EY26&FD$5,$EW$7:$EX$1101,2,FALSE) -> #N/A | FE26: =IFERROR(IF(EZ26>0,EZ$7),"") | FF26: =IFERROR(IF(FA26>0,FA$7),"") | FG26: =IFERROR(IF(FB26>0,FB$7),"") | FH26: =IFERROR(IF(FC26>0,FC$7),"") | FI26: =IFERROR(IF(FD26>0,FD$7),"") | FJ26: =FE26&FF26&FG26&FH26&FI26 | FK26: =IF(FJ26<>"",LEFT(FJ26,LEN(FJ26)-1),"") | FL26: =IF(FK26<>"",FK26&"として提供中","無") -> 無 | FN26: メゾン雑司ヶ谷 | FO26: 392000000
J27: 目白アパート2号館 | K27: 240000 | U27: 240000 | W27: 目白アパート | X27: 113432893 | Y27: 192559845 | AA27: 305992738 | AC27: 目白アパート1号館 | AD27: 51251000 | AE27: 5112000 | AG27: 56363000 | AI27: 目白アパート2号館 | AK27: 2000000 | AN27: 0 | AP27: 2000000 | AR27: 目白アパート | AT27: 0 | BB27: 0 | BF27: (空白) | BT27: 目白アパート2号館 | BX27: 160000 | CB27: 160000 | CJ27: 総計 | CK27: 33723144 | CL27: 35268300 | CM27: 35159540 | CO27: 295 | CP27: 190000 | CQ27: 16 | CS27: 20 | CT27: =VLOOKUP($CO27,chinryo_list,2,FALSE) -> 117 | CU27: =VLOOKUP($CO27,chinryo_list,3,FALSE) -> 高田馬場第4玉川ビル | CV27: =VLOOKUP($CO27,chinryo_list,4,FALSE) -> 101 | CW27: =VLOOKUP($CO27,chinryo_list,7,FALSE) -> 住居 | CX27: =VLOOKUP($CO27,chinryo_list,8,FALSE) -> 2SLDK | CY27: =VLOOKUP($CO27,chinryo_list,17,FALSE) -> 190000 | DB27: 170000-179999 | DC27: 4 | DD27: 685000 | DF27: (空白) | DJ27: (空白) | DY27: (空白) | EG27: 目白アパート1号2号_二棟一括 | EH27: 213926 | EI27: 100486 | EJ27: 314412 | EK27: 75151106 | EM27: 目白アパート | ES27: 20 | ET27: AG | EU27: AE | EV27: 21 | EW27: {=INDIRECT("'5借入一覧'!"&ET27&EV27)&INDIRECT("'5借入一覧'!"&EU27&EV27)} | EX27: 1 | EY27: 20 | EZ27: =VLOOKUP($EY27&EZ$5,$EW$7:$EX$1101,2,FALSE) -> #N/A | FA27: =VLOOKUP($EY27&FA$5,$EW$7:$EX$1101,2,FALSE) -> #N/A | FB27: =VLOOKUP($EY27&FB$5,$EW$7:$EX$1101,2,FALSE) -> #N/A | FC27: =VLOOKUP($EY27&FC$5,$EW$7:$EX$1101,2,FALSE) -> #N/A | FD27: =VLOOKUP($EY27&FD$5,$EW$7:$EX$1101,2,FALSE) -> #N/A | FE27: =IFERROR(IF(EZ27>0,EZ$7),"") | FF27: =IFERROR(IF(FA27>0,FA$7),"") | FG27: =IFERROR(IF(FB27>0,FB$7),"") | FH27: =IFERROR(IF(FC27>0,FC$7),"") | FI27: =IFERROR(IF(FD27>0,FD$7),"") | FJ27: =FE27&FF27&FG27&FH27&FI27 | FK27: =IF(FJ27<>"",LEFT(FJ27,LEN(FJ27)-1),"") | FL27: =IF(FK27<>"",FK27&"として提供中","無") -> 無 | FN27: レジデンス目白豊島 | FO27: 189000000
J28: プラウD目白301号 | O28: 7360 | Q28: 163200 | R28: 174000 | U28: 344560 | W28: 目白カーサ二番館 | X28: 59724146 | Y28: 252984606 | AA28: 312708752 | AC28: 目白アパート2号館 | AD28: 31236000 | AE28: 5241000 | AG28: 36477000 | AI28: プラウD目白301号 | AK28: 1131918 | AL28: 574046 | AP28: 1705964 | AR28: 目白カーサ二番館 | BF28: 目白アパート1号館 | BK28: 330000 | BP28: 330000 | BT28: 目白カーサ二番館 | BX28: 1758634 | BZ28: 113740 | CB28: 1872374 | CO28: 64 | CP28: 189444 | CQ28: 17 | CS28: 21 | CT28: =VLOOKUP($CO28,chinryo_list,2,FALSE) -> 103 | CU28: =VLOOKUP($CO28,chinryo_list,3,FALSE) -> カーサ目白台ハウス | CV28: =VLOOKUP($CO28,chinryo_list,4,FALSE) -> 102 | CW28: =VLOOKUP($CO28,chinryo_list,7,FALSE) -> 事務所 | CX28: =VLOOKUP($CO28,chinryo_list,8,FALSE) -> 事務所 | CY28: =VLOOKUP($CO28,chinryo_list,17,FALSE) -> 189444 | DB28: 180000-189999 | DC28: 4 | DD28: 725000 | DF28: 100000-199999 | DG28: 8 | DH28: 1406085 | DJ28: 目白アパート1号館 | DK28: 79 | DL28: 79056190 | DM28: 167336 | DN28: 35857 | DO28: 79 | DP28: 18910900 | DQ28: 264752 | DR28: 56732 | DS28: 158 | DT28: 97967090 | DU28: 432088 | DV28: 92589 | DY28: 目白アパート1号館 | EB28: 1 | EE28: 1 | EG28: 総計 | EH28: 12955677 | EI28: 5043759 | EJ28: 17999436 | EK28: 4439492417 | EM28: 目白カーサ二番館 | ES28: 21 | ET28: AG | EU28: AE | EV28: 22 | EW28: {=INDIRECT("'5借入一覧'!"&ET28&EV28)&INDIRECT("'5借入一覧'!"&EU28&EV28)} | EX28: 1 | EY28: 21 | EZ28: =VLOOKUP($EY28&EZ$5,$EW$7:$EX$1101,2,FALSE) -> #N/A | FA28: =VLOOKUP($EY28&FA$5,$EW$7:$EX$1101,2,FALSE) -> #N/A | FB28: =VLOOKUP($EY28&FB$5,$EW$7:$EX$1101,2,FALSE) -> #N/A | FC28: =VLOOKUP($EY28&FC$5,$EW$7:$EX$1101,2,FALSE) -> #N/A | FD28: =VLOOKUP($EY28&FD$5,$EW$7:$EX$1101,2,FALSE) -> #N/A | FE28: =IFERROR(IF(EZ28>0,EZ$7),"") | FF28: =IFERROR(IF(FA28>0,FA$7),"") | FG28: =IFERROR(IF(FB28>0,FB$7),"") | FH28: =IFERROR(IF(FC28>0,FC$7),"") | FI28: =IFERROR(IF(FD28>0,FD$7),"") | FJ28: =FE28&FF28&FG28&FH28&FI28 | FK28: =IF(FJ28<>"",LEFT(FJ28,LEN(FJ28)-1),"") | FL28: =IF(FK28<>"",FK28&"として提供中","無") -> 無 | FN28: 高田馬場第4玉川ビル | FO28: 118000000
J29: 総計 | K29: 14590219 | L29: 2296320 | M29: 2252388 | N29: 424404 | O29: 370580 | P29: 322080 | Q29: 211800 | R29: 190200 | T29: -6000 | U29: 20651991 | W29: (空白) | AC29: プラウD目白301号 | AD29: 37501218 | AE29: 57130988 | AG29: 94632206 | AI29: 総計 | AJ29: 433617 | AK29: 79840239 | AL29: 6753913 | AM29: 292843 | AN29: 0 | AP29: 87320612 | AR29: (空白) | BF29: 目白アパート2号館 | BK29: 160000 | BP29: 160000 | BT29: (空白) | CO29: 65 | CP29: 187000 | CQ29: 18 | CS29: 22 | CT29: =VLOOKUP($CO29,chinryo_list,2,FALSE) -> 103 | CU29: =VLOOKUP($CO29,chinryo_list,3,FALSE) -> カーサ目白台ハウス | CV29: =VLOOKUP($CO29,chinryo_list,4,FALSE) -> 103 | CW29: =VLOOKUP($CO29,chinryo_list,7,FALSE) -> 事務所 | CX29: =VLOOKUP($CO29,chinryo_list,8,FALSE) -> 事務所 | CY29: =VLOOKUP($CO29,chinryo_list,17,FALSE) -> 187000 | DB29: 190000-200000 | DC29: 3 | DD29: 586000 | DF29: アンテナ | DJ29: 目白アパート2号館 | DK29: 79 | DL29: 79056190 | DM29: 167336 | DN29: 35857 | DO29: 79 | DP29: 18910900 | DQ29: 264752 | DR29: 56732 | DS29: 158 | DT29: 97967090 | DU29: 432088 | DV29: 92589 | DY29: 目白アパート2号館 | EB29: 1 | EE29: 1 | EM29: (空白) | ES29: 22 | ET29: AG | EU29: AE | EV29: 23 | EW29: {=INDIRECT("'5借入一覧'!"&ET29&EV29)&INDIRECT("'5借入一覧'!"&EU29&EV29)} -> 106671 | EX29: 1 | EY29: 22 | EZ29: =VLOOKUP($EY29&EZ$5,$EW$7:$EX$1101,2,FALSE) -> #N/A | FA29: =VLOOKUP($EY29&FA$5,$EW$7:$EX$1101,2,FALSE) -> #N/A | FB29: =VLOOKUP($EY29&FB$5,$EW$7:$EX$1101,2,FALSE) -> #N/A | FC29: =VLOOKUP($EY29&FC$5,$EW$7:$EX$1101,2,FALSE) -> #N/A | FD29: =VLOOKUP($EY29&FD$5,$EW$7:$EX$1101,2,FALSE) -> #N/A | FE29: =IFERROR(IF(EZ29>0,EZ$7),"") | FF29: =IFERROR(IF(FA29>0,FA$7),"") | FG29: =IFERROR(IF(FB29>0,FB$7),"") | FH29: =IFERROR(IF(FC29>0,FC$7),"") | FI29: =IFERROR(IF(FD29>0,FD$7),"") | FJ29: =FE29&FF29&FG29&FH29&FI29 | FK29: =IF(FJ29<>"",LEFT(FJ29,LEN(FJ29)-1),"") | FL29: =IF(FK29<>"",FK29&"として提供中","無") -> 無 | FN29: 西池袋駅前ビル | FO29: 226000000
W30: 目白アパート1号館 | X30: 51251000 | Y30: 5112000 | AA30: 56363000 | AC30: 総計 | AD30: 1467635379 | AE30: 3694543297 | AG30: 5162178676 | AR30: 目白アパート1号館 | BF30: プラウD目白301号 | BK30: 0 | BP30: 0 | BT30: プラウD目白301号 | CO30: 178 | CP30: 185000 | CQ30: 19 | CS30: 23 | CT30: =VLOOKUP($CO30,chinryo_list,2,FALSE) -> 109 | CU30: =VLOOKUP($CO30,chinryo_list,3,FALSE) -> カーサ南池袋 | CV30: =VLOOKUP($CO30,chinryo_list,4,FALSE) -> 332 | CW30: =VLOOKUP($CO30,chinryo_list,7,FALSE) -> 住居 | CX30: =VLOOKUP($CO30,chinryo_list,8,FALSE) -> 3LDK | CY30: =VLOOKUP($CO30,chinryo_list,17,FALSE) -> 185000 | DB30: >200000 | DC30: 8 | DD30: 3466434 | DF30: その他 | DJ30: プラウD目白301号 | DK30: 79 | DL30: 6972378.2 | DM30: 98408 | DN30: 21087 | DO30: 62.47 | DP30: 22311426 | DQ30: 47872 | DR30: 10257 | DS30: 141.47 | DT30: 29283805 | DU30: 146280 | DV30: 31344 | DY30: プラウD目白301号 | EB30: 1 | EE30: 1 | EM30: 目白アパート1号館 | ES30: 23 | ET30: AG | EU30: AE | EV30: 24 | EW30: {=INDIRECT("'5借入一覧'!"&ET30&EV30)&INDIRECT("'5借入一覧'!"&EU30&EV30)} -> 107673 | EX30: 1 | EY30: 23 | EZ30: =VLOOKUP($EY30&EZ$5,$EW$7:$EX$1101,2,FALSE) -> #N/A | FA30: =VLOOKUP($EY30&FA$5,$EW$7:$EX$1101,2,FALSE) -> #N/A | FB30: =VLOOKUP($EY30&FB$5,$EW$7:$EX$1101,2,FALSE) -> #N/A | FC30: =VLOOKUP($EY30&FC$5,$EW$7:$EX$1101,2,FALSE) -> #N/A | FD30: =VLOOKUP($EY30&FD$5,$EW$7:$EX$1101,2,FALSE) -> #N/A | FE30: =IFERROR(IF(EZ30>0,EZ$7),"") | FF30: =IFERROR(IF(FA30>0,FA$7),"") | FG30: =IFERROR(IF(FB30>0,FB$7),"") | FH30: =IFERROR(IF(FC30>0,FC$7),"") | FI30: =IFERROR(IF(FD30>0,FD$7),"") | FJ30: =FE30&FF30&FG30&FH30&FI30 | FK30: =IF(FJ30<>"",LEFT(FJ30,LEN(FJ30)-1),"") | FL30: =IF(FK30<>"",FK30&"として提供中","無") -> 無 | FN30: 第3目白ハイツ | FO30: 495000000
W31: 目白アパート2号館 | X31: 31236000 | Y31: 5241000 | AA31: 36477000 | AR31: 目白アパート2号館 | BF31: 総計 | BG31: 247035 | BH31: 0 | BI31: 3702978 | BJ31: 0 | BK31: 27943232 | BL31: 282415 | BM31: 794721 | BN31: 2337093 | BP31: 35307474 | BT31: 総計 | BU31: 247035 | BV31: 3702978 | BW31: 0 | BX31: 27943232 | BY31: 282415 | BZ31: 794721 | CA31: 2337093 | CB31: 35307474 | CO31: 139 | CP31: 180000 | CQ31: 20 | CS31: 24 | CT31: =VLOOKUP($CO31,chinryo_list,2,FALSE) -> 106 | CU31: =VLOOKUP($CO31,chinryo_list,3,FALSE) -> 東池袋ハイツ | CV31: =VLOOKUP($CO31,chinryo_list,4,FALSE) -> 602 | CW31: =VLOOKUP($CO31,chinryo_list,7,FALSE) -> 住居 | CX31: =VLOOKUP($CO31,chinryo_list,8,FALSE) -> 1LDK | CY31: =VLOOKUP($CO31,chinryo_list,17,FALSE) -> 180000 | DB31: 総計 | DC31: 245 | DD31: 28235436 | DF31: 事務所 | DG31: 4 | DH31: 681592 | DJ31: 総計 | DK31: 12524.25 | DL31: 1.1890583e+09 | DM31: 9870447 | DN31: 2115462 | DO31: 5797.49 | DP31: 2.2216381e+09 | DQ31: 5583147 | DR31: 1196376 | DS31: 18321.74 | DT31: 3.4106964e+09 | DU31: 15453594 | DV31: 3311838 | DY31: 総計 | DZ31: 16 | EA31: 8 | EB31: 255 | EC31: 2 | ED31: 22 | EE31: 303 | EM31: プラウD目白301号 | ES31: 24 | ET31: AG | EU31: AE | EV31: 25 | EW31: {=INDIRECT("'5借入一覧'!"&ET31&EV31)&INDIRECT("'5借入一覧'!"&EU31&EV31)} -> 109673 | EX31: 1 | EY31: 24 | EZ31: =VLOOKUP($EY31&EZ$5,$EW$7:$EX$1101,2,FALSE) -> #N/A | FA31: =VLOOKUP($EY31&FA$5,$EW$7:$EX$1101,2,FALSE) -> #N/A | FB31: =VLOOKUP($EY31&FB$5,$EW$7:$EX$1101,2,FALSE) -> #N/A | FC31: =VLOOKUP($EY31&FC$5,$EW$7:$EX$1101,2,FALSE) -> #N/A | FD31: =VLOOKUP($EY31&FD$5,$EW$7:$EX$1101,2,FALSE) -> #N/A | FE31: =IFERROR(IF(EZ31>0,EZ$7),"") | FF31: =IFERROR(IF(FA31>0,FA$7),"") | FG31: =IFERROR(IF(FB31>0,FB$7),"") | FH31: =IFERROR(IF(FC31>0,FC$7),"") | FI31: =IFERROR(IF(FD31>0,FD$7),"") | FJ31: =FE31&FF31&FG31&FH31&FI31 | FK31: =IF(FJ31<>"",LEFT(FJ31,LEN(FJ31)-1),"") | FL31: =IF(FK31<>"",FK31&"として提供中","無") -> 無 | FN31: 池袋ハウス | FO31: 550000000
W32: プラウD目白301号 | X32: 19286259 | Y32: 57130988 | AA32: 76417247 | AR32: プラウD目白301号 | AW32: 295000 | BB32: 295000 | CO32: 176 | CP32: 180000 | CQ32: 20 | CS32: 25 | CT32: =VLOOKUP($CO32,chinryo_list,2,FALSE) -> 109 | CU32: =VLOOKUP($CO32,chinryo_list,3,FALSE) -> カーサ南池袋 | CV32: =VLOOKUP($CO32,chinryo_list,4,FALSE) -> 222 | CW32: =VLOOKUP($CO32,chinryo_list,7,FALSE) -> 住居 | CX32: =VLOOKUP($CO32,chinryo_list,8,FALSE) -> 3LDK | CY32: =VLOOKUP($CO32,chinryo_list,17,FALSE) -> 180000 | DF32: 自販機 | EM32: 目白アパート1号2号_二棟一括 | ES32: 25 | ET32: AG | EU32: AE | EV32: 26 | EW32: {=INDIRECT("'5借入一覧'!"&ET32&EV32)&INDIRECT("'5借入一覧'!"&EU32&EV32)} -> 109671 | EX32: 1 | EY32: 25 | EZ32: =VLOOKUP($EY32&EZ$5,$EW$7:$EX$1101,2,FALSE) -> #N/A | FA32: =VLOOKUP($EY32&FA$5,$EW$7:$EX$1101,2,FALSE) -> #N/A | FB32: =VLOOKUP($EY32&FB$5,$EW$7:$EX$1101,2,FALSE) -> #N/A | FC32: =VLOOKUP($EY32&FC$5,$EW$7:$EX$1101,2,FALSE) -> #N/A | FD32: =VLOOKUP($EY32&FD$5,$EW$7:$EX$1101,2,FALSE) -> #N/A | FE32: =IFERROR(IF(EZ32>0,EZ$7),"") | FF32: =IFERROR(IF(FA32>0,FA$7),"") | FG32: =IFERROR(IF(FB32>0,FB$7),"") | FH32: =IFERROR(IF(FC32>0,FC$7),"") | FI32: =IFERROR(IF(FD32>0,FD$7),"") | FJ32: =FE32&FF32&FG32&FH32&FI32 | FK32: =IF(FJ32<>"",LEFT(FJ32,LEN(FJ32)-1),"") | FL32: =IF(FK32<>"",FK32&"として提供中","無") -> 無 | FN32: 東池袋ハイツ | FO32: 376000000
