Workbook

Sheet 前提
B1: 高松二丁目 予実管理｜前提条件（青字＝入力、黄色＝確定待ち）
B3: 売買代金 | C3: 37000000 | D3: 契約ベース
B4: 手付金 | C4: 2000000 | D4: 各100万×売主2系統(合意済み)。決済時に代金充当
B5: 諸費用合計 | C5: 2487000 | D5: 諸費用明細の確定値(司法書士99.5万・火災保険19万見込み込み)
B6: 借入額 | C6: 37000000 | D6: 岩手銀行（根抵当極度額6,000万円）
B7: 金利（年率） | C7: 0.015 | D7: 仮置き1.5%。西原様確認中
B8: 融資期間（年） | C8: 25 | D8: 仮置き。西原様確認中
B9: 満室想定賃料/月（アーバンキューブ） | C9: 336000 | D9: レントロール実数: 8戸×42,000円(賃料4万+共益2千)満室
B10: 現況賃料/月（花みずき3棟・2/3入居） | C10: 108300 | D10: レントロール実数: 1号63,300+2号45,000。3号空室(再募集45,000)
B11: 想定入居率 | C11: 0.95 | D11: 想定
B12: PM管理料率（税込） | C12: 0.055 | D12: 想定
B13: BM・共用費/月 | C13: 30000 | D13: 仮置き（共用電気・浄化槽等）
B14: 火災保険料/年 | C14: 300000 | D14: 仮置き。見積取得後修正（毎年8月払い想定）
... B18: 想定退去件数/年 | C18: 2 | D18: トリガー試算用
B20: 月次返済額（元利均等） | C20: =-PMT(前提!$C$7/12,前提!$C$8*12,前提!$C$6) | D20: 金利・期間確定で自動更新
B21: 想定実効賃料/月 | C21: =(前提!$C$9+前提!$C$10)*前提!$C$11
B22: PM管理料/月 | C22: =(前提!$C$9+前提!$C$10)*前提!$C$11*前提!$C$12
B23: 決済時必要自己資金 | C23: =前提!$C$3+前提!$C$5-前提!$C$6 | D23: 手付は代金充当前提

Sheet 月次予実
A1: 月次キャッシュフロー予実（2026/07〜2029/12）
A3: 年月 | B3: イベント | C3: 予定収入 | D3: 予定返済 | E3: 予定運営費 | F3: 予定税・保険 | G3: 予定NetCF | H3: 予定累計CF | I3: 実績収入 | J3: 実績支出 | K3: 実績NetCF（自動） | L3: 差異メモ
A4: 2026/07 | B4: 7/31契約・手付支払 | C4: 0 | D4: 0 | E4: 0 | F4: =前提!$C$4 | G4: =C4-D4-E4-F4 | H4: =G4 | K4: =IF(AND(I4="",J4=""),"",I4-J4)
A5: 2026/08 | B5: 8/14決済（自己資金拠出・融資実行）／8/7手付解除期日、残自己資金拠出 | C5: 0 | D5: 0 | E5: 0 | F5: =前提!$C$23-前提!$C$4 | G5: =C5-D5-E5-F5 | H5: =H4+G5 | K5: =IF(AND(I5="",J5=""),"",I5-J5)
A6: 2026/09 | B6: 退去シーズン→退去発生時は前提!退去費用を実績に計上 | C6: =前提!$C$21 | D6: =前提!$C$20 | E6: =前提!$C$22+前提!$C$13 | F6: 0 | G6: =C6-D6-E6-F6 | H6: =H5+G6 | K6: =IF(AND(I6="",J6=""),"",I6-J6)
A7: 2026/10 | C7: =前提!$C$21 | D7: =前提!$C$20 | E7: =前提!$C$22+前提!$C$13 | F7: 0 | G7: =C7-D7-E7-F7 | H7: =H6+G7 | K7: =IF(AND(I7="",J7=""),"",I7-J7)
A8: 2026/11 | C8: =前提!$C$21 | D8: =前提!$C$20 | E8: =前提!$C$22+前提!$C$13 | F8: 0 | G8: =C8-D8-E8-F8 | H8: =H7+G8 | K8: =IF(AND(I8="",J8=""),"",I8-J8)
A9: 2026/12 | C9: =前提!$C$21 | D9: =前提!$C$20 | E9: =前提!$C$22+前提!$C$13 | F9: 0 | G9: =C9-D9-E9-F9 | H9: =H8+G9 | K9: =IF(AND(I9="",J9=""),"",I9-J9)
A10: 2027/01 | C10: =前提!$C$21 | D10: =前提!$C$20 | E10: =前提!$C$22+前提!$C$13 | F10: 0 | G10: =C10-D10-E10-F10 | H10: =H9+G10 | K10: =IF(AND(I10="",J10=""),"",I10-J10)
A11: 2027/02 | B11: 不動産取得税 納付想定 | C11: =前提!$C$21 | D11: =前提!$C$20 | E11: =前提!$C$22+前提!$C$13 | F11: =前提!$C$16 | G11: =C11-D11-E11-F11 | H11: =H10+G11 | K11: =IF(AND(I11="",J11=""),"",I11-J11)
A12: 2027/03 | B12: 退去シーズン→退去発生時は前提!退去費用を実績に計上 | C12: =前提!$C$21 | D12: =前提!$C$20 | E12: =前提!$C$22+前提!$C$13 | F12: 0 | G12: =C12-D12-E12-F12 | H12: =H11+G12 | K12: =IF(AND(I12="",J12=""),"",I12-J12)
A13: 2027/04 | C13: =前提!$C$21 | D13: =前提!$C$20 | E13: =前提!$C$22+前提!$C$13 | F13: 0 | G13: =C13-D13-E13-F13 | H13: =H12+G13 | K13: =IF(AND(I13="",J13=""),"",I13-J13)
A14: 2027/05 | B14: 固都税納付（一括想定） | C14: =前提!$C$21 | D14: =前提!$C$20 | E14: =前提!$C$22+前提!$C$13 | F14: =前提!$C$15 | G14: =C14-D14-E14-F14 | H14: =H13+G14 | K14: =IF(AND(I14="",J14=""),"",I14-J14)
A15: 2027/06 | C15: =前提!$C$21 | D15: =前提!$C$20 | E15: =前提!$C$22+前提!$C$13 | F15: 0 | G15: =C15-D15-E15-F15 | H15: =H14+G15 | K15: =IF(AND(I15="",J15=""),"",I15-J15)
A16: 2027/07 | C16: =前提!$C$21 | D16: =前提!$C$20 | E16: =前提!$C$22+前提!$C$13 | F16: 0 | G16: =C16-D16-E16-F16 | H16: =H15+G16 | K16: =IF(AND(I16="",J16=""),"",I16-J16)
A17: 2027/08 | B17: 火災保険 年払い・保険見直し、【トリガー】保有1年レビュー（賃料・修繕・売却打診） | C17: =前提!$C$21 | D17: =前提!$C$20 | E17: =前提!$C$22+前提!$C$13 | F17: =前提!$C$14 | G17: =C17-D17-E17-F17 | H17: =H16+G17 | K17: =IF(AND(I17="",J17=""),"",I17-J17)
A18: 2027/09 | B18: 退去シーズン→退去発生時は前提!退去費用を実績に計上 | C18: =前提!$C$21 | D18: =前提!$C$20 | E18: =前提!$C$22+前提!$C$13 | F18: 0 | G18: =C18-D18-E18-F18 | H18: =H17+G18 | K18: =IF(AND(I18="",J18=""),"",I18-J18)
A19: 2027/10 | C19: =前提!$C$21 | D19: =前提!$C$20 | E19: =前提!$C$22+前提!$C$13 | F19: 0 | G19: =C19-D19-E19-F19 | H19: =H18+G19 | K19: =IF(AND(I19="",J19=""),"",I19-J19)
A20: 2027/11 | C20: =前提!$C$21 | D20: =前提!$C$20 | E20: =前提!$C$22+前提!$C$13 | F20: 0 | G20: =C20-D20-E20-F20 | H20: =H19+G20 | K20: =IF(AND(I20="",J20=""),"",I20-J20)
A21: 2027/12 | C21: =前提!$C$21 | D21: =前提!$C$20 | E21: =前提!$C$22+前提!$C$13 | F21: 0 | G21: =C21-D21-E21-F21 | H21: =H20+G21 | K21: =IF(AND(I21="",J21=""),"",I21-J21)
A22: 2028/01 | C22: =前提!$C$21 | D22: =前提!$C$20 | E22: =前提!$C$22+前提!$C$13 | F22: 0 | G22: =C22-D22-E22-F22 | H22: =H21+G22 | K22: =IF(AND(I22="",J22=""),"",I22-J22)
A23: 2028/02 | C23: =前提!$C$21 | D23: =前提!$C$20 | E23: =前提!$C$22+前提!$C$13 | F23: 0 | G23: =C23-D23-E23-F23 | H23: =H22+G23 | K23: =IF(AND(I23="",J23=""),"",I23-J23)
A24: 2028/03 | B24: 退去シーズン→退去発生時は前提!退去費用を実績に計上 | C24: =前提!$C$21 | D24: =前提!$C$20 | E24: =前提!$C$22+前提!$C$13 | F24: 0 | G24: =C24-D24-E24-F24 | H24: =H23+G24 | K24: =IF(AND(I24="",J24=""),"",I24-J24)
A25: 2028/04 | C25: =前提!$C$21 | D25: =前提!$C$20 | E25: =前提!$C$22+前提!$C$13 | F25: 0 | G25: =C25-D25-E25-F25 | H25: =H24+G25 | K25: =IF(AND(I25="",J25=""),"",I25-J25)
A26: 2028/05 | B26: 固都税納付（一括想定） | C26: =前提!$C$21 | D26: =前提!$C$20 | E26: =前提!$C$22+前提!$C$13 | F26: =前提!$C$15 | G26: =C26-D26-E26-F26 | H26: =H25+G26 | K26: =IF(AND(I26="",J26=""),"",I26-J26)
A27: 2028/06 | C27: =前提!$C$21 | D27: =前提!$C$20 | E27: =前提!$C$22+前提!$C$13 | F27: 0 | G27: =C27-D27-E27-F27 | H27: =H26+G27 | K27: =IF(AND(I27="",J27=""),"",I27-J27)
A28: 2028/07 | C28: =前提!$C$21 | D28: =前提!$C$20 | E28: =前提!$C$22+前提!$C$13 | F28: 0 | G28: =C28-D28-E28-F28 | H28: =H27+G28 | K28: =IF(AND(I28="",J28=""),"",I28-J28)
A29: 2028/08 | B29: 火災保険 年払い・保険見直し、【トリガー】保有2年レビュー／金利改定確認 | C29: =前提!$C$21 | D29: =前提!$C$20 | E29: =前提!$C$22+前提!$C$13 | F29: =前提!$C$14 | G29: =C29-D29-E29-F29 | H29: =H28+G29 | K29: =IF(AND(I29="",J29=""),"",I29-J29)
A30: 2028/09 | B30: 退去シーズン→退去発生時は前提!退去費用を実績に計上 | C30: =前提!$C$21 | D30: =前提!$C$20 | E30: =前提!$C$22+前提!$C$13 | F30: 0 | G30: =C30-D30-E30-F30 | H30: =H29+G30 | K30: =IF(AND(I30="",J30=""),"",I30-J30)
A31: 2028/10 | C31: =前提!$C$21 | D31: =前提!$C$20 | E31: =前提!$C$22+前提!$C$13 | F31: 0 | G31: =C31-D31-E31-F31 | H31: =H30+G31 | K31: =IF(AND(I31="",J31=""),"",I31-J31)
A32: 2028/11 | C32: =前提!$C$21 | D32: =前提!$C$20 | E32: =前提!$C$22+前提!$C$13 | F32: 0 | G32: =C32-D32-E32-F32 | H32: =H31+G32 | K32: =IF(AND(I32="",J32=""),"",I32-J32)
A33: 2028/12 | C33: =前提!$C$21 | D33: =前提!$C$20 | E33: =前提!$C$22+前提!$C$13 | F33: 0 | G33: =C33-D33-E33-F33 | H33: =H32+G33 | K33: =IF(AND(I33="",J33=""),"",I33-J33)
A34: 2029/01 | C34: =前提!$C$21 | D34: =前提!$C$20 | E34: =前提!$C$22+前提!$C$13 | F34: 0 | G34: =C34-D34-E34-F34 | H34: =H33+G34 | K34: =IF(AND(I34="",J34=""),"",I34-J34)
A35: 2029/02 | C35: =前提!$C$21 | D35: =前提!$C$20 | E35: =前提!$C$22+前提!$C$13 | F35: 0 | G35: =C35-D35-E35-F35 | H35: =H34+G35 | K35: =IF(AND(I35="",J35=""),"",I35-J35)
A36: 2029/03 | B36: 退去シーズン→退去発生時は前提!退去費用を実績に計上 | C36: =前提!$C$21 | D36: =前提!$C$20 | E36: =前提!$C$22+前提!$C$13 | F36: 0 | G36: =C36-D36-E36-F36 | H36: =H35+G36 | K36: =IF(AND(I36="",J36=""),"",I36-J36)
A37: 2029/04 | C37: =前提!$C$21 | D37: =前提!$C$20 | E37: =前提!$C$22+前提!$C$13 | F37: 0 | G37: =C37-D37-E37-F37 | H37: =H36+G37 | K37: =IF(AND(I37="",J37=""),"",I37-J37)
A38: 2029/05 | B38: 固都税納付（一括想定） | C38: =前提!$C$21 | D38: =前提!$C$20 | E38: =前提!$C$22+前提!$C$13 | F38: =前提!$C$15 | G38: =C38-D38-E38-F38 | H38: =H37+G38 | K38: =IF(AND(I38="",J38=""),"",I38-J38)
A39: 2029/06 | C39: =前提!$C$21 | D39: =前提!$C$20 | E39: =前提!$C$22+前提!$C$13 | F39: 0 | G39: =C39-D39-E39-F39 | H39: =H38+G39 | K39: =IF(AND(I39="",J39=""),"",I39-J39)
A40: 2029/07 | C40: =前提!$C$21 | D40: =前提!$C$20 | E40: =前提!$C$22+前提!$C$13 | F40: 0 | G40: =C40-D40-E40-F40 | H40: =H39+G40 | K40: =IF(AND(I40="",J40=""),"",I40-J40)
A41: 2029/08 | B41: 火災保険 年払い・保険見直し、【トリガー】保有3年レビュー／売却 vs 継続の判定 | C41: =前提!$C$21 | D41: =前提!$C$20 | E41: =前提!$C$22+前提!$C$13 | F41: =前提!$C$14 | G41: =C41-D41-E41-F41 | H41: =H40+G41 | K41: =IF(AND(I41="",J41=""),"",I41-J41)
...

Sheet トリガー管理
A1: イベント・トリガー管理（発生したら月次予実の実績列へ反映）
A3: トリガー | B3: 発生条件・時期 | C3: 影響額(概算/年) | D3: 対応アクション | E3: 状態 | F3: 備考
A4: 退去発生 | B4: 退去通知受領時（3月・9月要警戒） | C4: =前提!$C$17*前提!$C$18 | D4: 原状回復→再募集。花みずき側は解体前提なら再募集せず空室維持も選択肢 | E4: 監視中 | F4: 大学生協/トラステンから通知
A5: 金利上昇 +0.5% | B5: 岩銀の基準金利改定時 | C5: =前提!$C$6*0.005 | D5: 返済額再計算→前提!金利を更新。+1.0%超なら繰上返済・借換え検討 | E5: 監視中 | F5: 利息増加分の年額
A6: 金利上昇 +1.0% | B6: 同上 | C6: =前提!$C$6*0.01 | D6: 借換え見積（北日本銀行・公庫）＋売却検討ラインへ | E6: 監視中
A7: 大規模修繕の兆候 | B7: 雨漏り・外壁・設備故障の報告時 | C7: 0 | D7: 見積2社→修繕 vs 売却の採算比較 | E7: 未発生 | F7: 築年数要確認
A8: 花みずき全空 | B8: 3棟とも退去した時点 | C8: 0 | D8: 解体（東日産業見積あり）→新築 or 更地売却の判断 | E8: 未発生 | F8: 解体費見積は取得済み
A9: 保険更新 | B9: 毎年8月 | C9: =前提!$C$14 | D9: 保険料改定チェック・補償内容見直し（水災・地震特約） | E9: 毎年 | F9: アズール岩尾/持田さんに相見積可
A10: 売却検討ライン | B10: 保有3年経過（2029/8）or 金利+1%超 or 空室率30%超 | C10: 0 | D10: 収支実績3年分で査定→売却 vs 継続。想定利回り8%で逆算 | E10: 未発生 | F10: 予実シートの累計CFで判断
