Workbook

Sheet ①物件情報入力シート
A1: シート作成日 | C1: 2026/6/10 | M1: 用途地域 | N1: 建築年 | O1: 築年数 | P1: 構造 | Q1: 耐用年数 | R1: 間取り | S1: リフォーム費用 | T1: 借地権割合 | V1: リフォーム単価
A2: 土地情報 | M2: 第一種低層住居専用地域 | N2: 1926年(大正15年・昭和元年) | O2: 100 | P2: 木造 | Q2: 22 | R2: 1R | S2: 2000000 | T2: A | U2: 水回り | V2: 2000000
B3: 住所 | C3: 藤沢市辻堂東海岸3-3-20 | M3: 第二種低層住居専用地域 | N3: 1927年(昭和2年) | O3: 99 | P3: 軽量鉄骨造 | Q3: 27 | R3: 1K | S3: =V2+V3 | T3: B | U3: 1部屋につき | V3: 400000
B4: 地番 | C4: 藤沢市辻堂東海岸3丁目7239-245 | M4: 第一種中高層住居専用地域 | N4: 1928年(昭和3年) | O4: 98 | P4: 重量鉄骨造 | Q4: 34 | R4: 1DK | S4: =S3+V3 | T4: C
B5: 敷地面積 | C5: 139.8 | D5: ㎡ | E5: =C5/3.305 | F5: 坪 | M5: 第二種中高層住居専用地域 | N5: 1929年(昭和4年) | O5: 97 | P5: RC造 | Q5: 47 | R5: 2K | S5: =S4 | T5: D
B6: 用途地域 | C6: 第一種住居地域 | M6: 第一種住居地域 | N6: 1930年(昭和5年) | O6: 96 | P6: SRC造 | Q6: 47 | R6: 1LDK | S6: =S5+$V$3 | T6: E
B7: 建蔽率 | C7: 0.6 | D7: 建蔽率・容積率のHP | M7: 第二種住居地域 | N7: 1931年(昭和6年) | O7: 95 | R7: 2DK | S7: =S6 | T7: F
B8: 容積率 | C8: 2 | M8: 準住居地域 | N8: 1932年(昭和7年) | O8: 94 | R8: 3K | S8: =S6 | T8: G
B9: 交通 | C9: 東海道 | D9: 線 | E9: =C9&D9&"「"&C10&"」"&D10&B11&C11&D11 | M9: 田園住居地域 | N9: 1933年(昭和8年) | O9: 93 | R9: 2LDK | S9: =S8+$V$3
B10: 駅 | C10: 辻堂 | D10: 駅 | M10: 近隣商業地域 | N10: 1934年(昭和9年) | O10: 92 | R10: 3DK | S10: =S9
B11: 徒歩 | C11: 27 | D11: 分 | M11: 商業地域 | N11: 1935年(昭和10年) | O11: 91 | R11: 4K | S11: =S9
A12: 建物情報 | M12: 準工業地域 | N12: 1936年(昭和11年) | O12: 90 | R12: 3LDK | S12: =S11+$V$3
B13: 建築年 | C13: 2016年(平成28年) | E13: 築年数 | F13: =VLOOKUP(C13,N:O,2,1) | G13: 年 | H13: 残耐用年数 | I13: =F14-F13 | J13: 年 | M13: 工業地域 | N13: 1937年(昭和12年) | O13: 89 | R13: 4DK | S13: =S12
B14: 構造・種類 | C14: 木造 | E14: 耐用年数 | F14: =VLOOKUP(C14,P:Q,2,0) | G14: 年 | H14: =C13&" 築"&F13&"年" | M14: 工業専用地域 | N14: 1938年(昭和13年) | O14: 88 | R14: 5K | S14: =S12
B15: 間取り | C15: 3LDK | E15: 内装リフォーム | F15: =VLOOKUP(C15,R:S,2,0) | M15: 非線引き区域 | N15: 1939年(昭和14年) | O15: 87 | R15: 4LDK | S15: =S14+$V$3
B16: 階高 | C16: 2階建て | M16: 市街化調整区域 | N16: 1940年(昭和15年) | O16: 86 | R16: 5DK | S16: =S15
B17: 1階 | C17: 50.51 | D17: ㎡ | E17: (現状建蔽率) | F17: =C17/C5 | G17: 判定⇒ | H17: =IF(F17<=C7,"OK","NG") | N17: 1941年(昭和16年) | O17: 85 | R17: 6K | S17: =S15
B18: 2階 | C18: 19.87 | D18: ㎡ | E18: 延床面積 | F18: =SUM(C17:C19) | G18: ㎡ | H18: =F18/3.305 | I18: 坪 | N18: 1942年(昭和17年) | O18: 84 | R18: 5LDK | S18: =S17+$V$3
B19: 3階 | D19: ㎡ | E19: (現状容積率) | F19: =F18/C5 | G19: 判定⇒ | H19: =IF(F19<=MIN(C8,C21*C20),"OK","NG") | N19: 1943年(昭和18年) | O19: 83 | R19: 6DK | S19: =S18
B20: 前面道路幅員 | C20: 4.6 | D20: m | N20: 1944年(昭和19年) | O20: 82
B21: 容積率低減係数 | C21: 0.4 | N21: 1945年(昭和20年) | O21: 81
N22: 1946年(昭和21年) | O22: 80
A23: 固定資産税路線価（全国地価マップより、公示価格の70%） | N23: 1947年(昭和22年) | O23: 79
C24: 166000 | D24: 円/㎡ | G24: ⇒土地積算評価(固定) | I24: =C24*C5 | J24: 円 | N24: 1948年(昭和23年) | O24: 78
A25: 相続税路線価（全国地価マップより、公示価格の80%） | N25: 1949年(昭和24年) | O25: 77
C26: =C24/0.7*0.8/1000 | D26: E | E26: =C26*1000 | F26: 円/㎡ | G26: ⇒土地積算評価(相続) | I26: =E26*C5 | J26: 円 | N26: 1950年(昭和25年) | O26: 76
A27: 公示価格（固定資産税路線価÷0.7） | N27: 1951年(昭和26年) | O27: 75
C28: =C24/0.7 | E28: =C24/0.7 | F28: 円/㎡ | G28: ⇒土地積算評価(公示) | I28: =E28*C5 | J28: 円 | N28: 1952年(昭和27年) | O28: 74
A29: 再調達価格 | C29: 再調達価格のHP | N29: 1953年(昭和28年) | O29: 73
C30: 100000 | D30: 円/㎡ | G30: ⇒建物積算評価 | I30: =MAX(0,F18*C30*(I13/F14)) | J30: 円 | N30: 1954年(昭和29年) | O30: 72
N31: 1955年(昭和30年) | O31: 71
A32: 積算価格（固定資産税路線価+建物積算） | I32: =I24+I30 | J32: 円 | N32: 1956年(昭和31年) | O32: 70
N33: 1957年(昭和32年) | O33: 69
A34: 国交省取引平均価格 | C34: 国土交通省HP | N34: 1958年(昭和33年) | O34: 68
C35: 200000 | D35: 円/坪 | G35: ⇒土地概算(国交省) | I35: =C35*E5 | J35: 円 | N35: 1959年(昭和34年) | O35: 67
N36: 1960年(昭和35年) | O36: 66
A37: 想定賃料(円) | N37: 1961年(昭和36年) | O37: 65
C38: 140000 | D38: 円～ | E38: 賃料平均 | F38: =AVERAGE(C38:C39) | N38: 1962年(昭和37年) | O38: 64
C39: 140000 | D39: 円 | N39: 1963年(昭和38年) | O39: 63
N40: 1964年(昭和39年) | O40: 62
...

Sheet ②（土地・建物）事業収支シート
A1: ■１棟（土地・建物） 事 業 収 支 | J1: 作成日 | K1: =①物件情報入力シート!C1
A2: 仕入時 | B2: 販売時 | C2: 原価確定時 | M2: 46388
J3: 社長 | K3: 営業担当
A6: 物件名 | B6: =①物件情報入力シート!C3 | G6: 仕入契約予定 | H6: =TODAY()+20 | J6: 仕入決済予定 | K6: =H6+30
A7: 所在地番 | B7: =①物件情報入力シート!C4 | G7: 売却契約予定 | H7: =H6+90 | J7: 売却決済予定 | K7: =H7+30
K8: ="仕入れから売却まで "&_xlfn.DAYS(K7,K6)&" 日間"
A9: 物 件 概 要 | G9: 査定参考金額 | J9: 年間固定資産税 | K9: =J13*0.02
A10: 敷地面積 | B10: =①物件情報入力シート!E5 | C10: =①物件情報入力シート!C5 | G10: 国交省取引価格 | H10: =①物件情報入力シート!I35 | J10: 年間管理費 | K10: 0
A11: 延床面積 | B11: =①物件情報入力シート!H18 | C11: =①物件情報入力シート!F18 | G11: AI査定より | H11: =①物件情報入力シート!F42 | J11: 実勢価格係数 | K11: 1.5
A12: 1階 | B12: =①物件情報入力シート!C17 | C12: 2階以上 | D12: =①物件情報入力シート!C18+①物件情報入力シート!C19 | G12: 月額想定賃料 | H12: =①物件情報入力シート!F38 | J12: 土地積算評価 | K12: 土地実勢価格
A13: 用途地域 | B13: =①物件情報入力シート!C6 | G13: 固定資産税路線価 | H13: =①物件情報入力シート!C24 | J13: =①物件情報入力シート!I24 | K13: =J14/0.8*K11
A14: 建蔽率 | B14: =①物件情報入力シート!C7 | C14: 現況建蔽率 | D14: =①物件情報入力シート!F17 | E14: =①物件情報入力シート!H17 | G14: 相続税路線価 | H14: =①物件情報入力シート!E26 | J14: =①物件情報入力シート!I26 | K14: ビルダー目線
A15: 容積率 | B15: =①物件情報入力シート!C8 | C15: 現況容積率 | D15: =①物件情報入力シート!F19 | E15: =①物件情報入力シート!H19 | G15: 公示価格 | H15: =①物件情報入力シート!E28 | J15: =①物件情報入力シート!I28 | K15: =K13*0.8
A16: 築年数 | B16: =①物件情報入力シート!H14 | G16: 再調達価格のHP | J16: 建物積算価格 | K16: 売却価格での利回り
A17: 構造・階高 | B17: =①物件情報入力シート!C14 | C17: =①物件情報入力シート!C16 | D17: 間取り | E17: =①物件情報入力シート!C15 | G17: 再調達価格 | H17: =①物件情報入力シート!C30 | J17: =①物件情報入力シート!I30 | K17: =H12*12/M22
A18: 交通 | B18: =①物件情報入力シート!E9
G19: 積算価格(固定資産税路線価+建物積算価格) | K19: =①物件情報入力シート!I32
A21: 売上 | G21: 入金元 | H21: 税抜 | I21: 消費税 | K21: 入金予定 | L21: チェックリスト
A22: 売却費（土地） | B22: =B10 | C22: × | D22: =H22/B22 | E22: 1 | H22: =M22*E22 | I22: - | K22: =$K$7 | M22: 35000000
A23: 売却費（建物） | B23: =B11 | C23: × | D23: =H23/B23 | E23: =1-E22 | H23: =M22*E23/1.1 | I23: =H23*0.1
A24: 固都税精算金 | B24: =M2-K7 | C24: 日分受領 | H24: =K9*B24/365 | I24: -
A25: 管理費精算金 | B25: =M2-K7 | C25: 日分受領 | H25: =K10*B25/365 | I25: -
A26: 紹介料 | B26: 工務店紹介料 | I26: =H26*0.1
A27: 原価 | G27: 支払先 | H27: 税抜 | J27: 消費税 | K27: 支払予定 | L27: チェックリスト
A28: 手付金 | B28: 購入金額の | C28: =H28/M29 | G28: 売主 | H28: 0 | I28: - | K28: =H6
A29: 取得費（土地） | B29: =B10 | C29: × | D29: =H29/B29 | E29: 1 | G29: 売主 | H29: =(M29-H28)*E29 | I29: - | K29: =$K$6 | M29: 24000000
A30: 取得費（建物） | B30: =B11 | C30: × | D30: =H30/B30 | E30: =1-E29 | G30: 売主 | H30: =(M29-H28)*E30/1.1 | I30: =H30*0.1
A31: 固都税精算金 | B31: =M2-K6 | C31: 日分支払い | G31: 売主 | H31: =K9*B31/365 | I31: -
A32: 管理費精算金 | B32: =M2-K6 | C32: 日分支払い | G32: 売主 | H32: =K10*B32/365 | I32: - | L32: □請求書 □支払（ / ）
A33: （買）仲介 | B33: 800万円未満の契約は33万円※R6.7.1より※ | G33: (買)仲介業者 | H33: =IF(M29>=8000000,M29*0.03+60000,300000) | I33: =H33*0.1 | L33: □請求書 □支払（ / ）
A34: 立退費 | B34: 立退相場 | C34: 1000000 | D34: × | E34: 0 | H34: 0 | I34: =H34*0.1 | K34: =IF(H34>0,"入力してください!","") | L34: □請求書 □支払（ / ）
A35: 解体費 | B35: 解体相場 | D35: × | E35: =B11 | H35: =C35*E35 | I35: =H35*0.1 | K35: =IF(H35>0,"入力してください!","") | L35: □請求書 □支払（ / ）
A36: 造成費 | B36: 造成工事・整地・遺跡発掘 | H36: 0 | I36: =H36*0.1 | K36: =IF(H36>0,"入力してください!","") | L36: □請求書 □支払（ / ）
A37: 開発費 | B37: 公共負担金・開発許認可 | H37: 0 | I37: =H37*0.1 | K37: =IF(H37>0,"入力してください!","") | L37: □請求書 □支払（ / ）
A38: 測量費 | B38: ボーリング・各種測量費 | H38: 0 | I38: =H38*0.1 | K38: =IF(H38>0,"入力してください!","") | L38: □請求書 □支払（ / ）
A39: 近隣補償費 | B39: 直接補償 | H39: 0 | I39: =H39*0.1 | K39: =IF(H39>0,"入力してください!","") | L39: □請求書 □支払（ / ）
A40: 設計監理 | B40: 設計監理委託料 | H40: 0 | I40: =H40*0.1 | K40: =IF(H40>0,"入力してください!","") | L40: □請求書 □支払（ / ）
A41: 業務委託 | B41: ①近隣業務委託費 | H41: 0 | I41: =H41*0.1 | K41: =IF(H41>0,"入力してください!","") | L41: □請求書 □支払（ / ）
B42: ②認可取得業務・申請料 | H42: 0 | I42: =H42*0.1 | K42: =IF(H42>0,"入力してください!","") | L42: □請求書 □支払（ / ）
A43: その他 | B43: 残置物撤去費用 | H43: 0 | I43: =H43*0.1 | K43: =IF(H43>0,"入力してください!","") | L43: □請求書 □支払（ / ）
...

Sheet 利回り参考
A1: 平均賃料相場
B2: =①物件情報入力シート!F38 | C2: 売却・都内 | F2: 売却・都内：サイケンフ
F3: 売却・16号線内側 | I3: 売却・16号線内側：サイケンフ
I4: 売却・16号線外側：サイケンフ | L4: 売却・16号線外側：サイケンフ
C5: 0.07 | D5: 0.08 | E5: 0.09 | F5: 0.1 | G5: 0.11 | H5: 0.12 | I5: 0.13 | J5: 0.14 | K5: 0.15 | L5: 0.16 | M5: 0.17 | N5: 0.18 | O5: 0.19 | P5: 0.2 | Q5: 0.21 | R5: 0.22 | S5: 0.23 | T5: 0.24 | U5: 0.25 | V5: 0.26 | W5: 0.27 | X5: 0.28 | Y5: 0.29 | Z5: 0.3
B6: =B7-1000 | C6: =$B6*12/C$5 | D6: =$B6*12/D$5 | E6: =$B6*12/E$5 | F6: =$B6*12/F$5 | G6: =$B6*12/G$5 | H6: =$B6*12/H$5 | I6: =$B6*12/I$5 | J6: =$B6*12/J$5 | ... Z6: =$B6*12/Z$5
B7: =B8-1000 | C7: =$B7*12/C$5 | D7: =$B7*12/D$5 | E7: =$B7*12/E$5 | F7: =$B7*12/F$5 | G7: =$B7*12/G$5 | H7: =$B7*12/H$5 | I7: =$B7*12/I$5 | J7: =$B7*12/J$5 | ... Z7: =$B7*12/Z$5
B8: =B9-1000 | C8: =$B8*12/C$5 | D8: =$B8*12/D$5 | E8: =$B8*12/E$5 | F8: =$B8*12/F$5 | G8: =$B8*12/G$5 | H8: =$B8*12/H$5 | I8: =$B8*12/I$5 | J8: =$B8*12/J$5 | ... Z8: =$B8*12/Z$5
B9: =B2 | C9: =$B9*12/C$5 | D9: =$B9*12/D$5 | E9: =$B9*12/E$5 | F9: =$B9*12/F$5 | G9: =$B9*12/G$5 | H9: =$B9*12/H$5 | I9: =$B9*12/I$5 | J9: =$B9*12/J$5 | ... Z9: =$B9*12/Z$5
B10: =B9+1000 | C10: =$B10*12/C$5 | D10: =$B10*12/D$5 | E10: =$B10*12/E$5 | F10: =$B10*12/F$5 | G10: =$B10*12/G$5 | H10: =$B10*12/H$5 | I10: =$B10*12/I$5 | J10: =$B10*12/J$5 | ... Z10: =$B10*12/Z$5
B11: =B10+1000 | C11: =$B11*12/C$5 | D11: =$B11*12/D$5 | E11: =$B11*12/E$5 | F11: =$B11*12/F$5 | G11: =$B11*12/G$5 | H11: =$B11*12/H$5 | I11: =$B11*12/I$5 | J11: =$B11*12/J$5 | ... Z11: =$B11*12/Z$5
B12: =B11+1000 | C12: =$B12*12/C$5 | D12: =$B12*12/D$5 | E12: =$B12*12/E$5 | F12: =$B12*12/F$5 | G12: =$B12*12/G$5 | H12: =$B12*12/H$5 | I12: =$B12*12/I$5 | J12: =$B12*12/J$5 | ... Z12: =$B12*12/Z$5

Sheet 持ち物リスト
B1: No.XXX | C1: 案件名 | E1: =①物件情報入力シート!C3 | X1: 契約形態 | Y1: 契約方法 | Z1: 司法書士(買い) | AA1: 司法書士(売り) | AB1: 領収書 | AC1: 持ち物準備する人
C2: 物件住所 | E2: =①物件情報入力シート!C3 | X2: 通常売買(仲介あり)→所有権移転→売却 | Y2: 対面契約 | Z2: 売主指定 | AA2: 買主指定 | AB2: 不要 | AC2: 江藤
C3: 仲介会社 | E3: 株式会社ABC不動産販売 | L3: 仲介会社 | N3: 株式会社TSUKUBITO | X3: 通常売買(仲介なし)→所有権移転→売却 | Y3: 持ち回り契約 | Z3: バイセル指定 | AA3: バイセル指定 | AB3: 電子 | AC3: 担当営業
C4: 担当者 | E4: 山田哲人 | L4: 担当者 | X4: 三為契約(仲介あり) | Y4: 電子契約(オンライン) | Z4: 仲介指定 | AA4: 仲介指定 | AB4: 紙(印紙不要) | AC4: 仲介
C5: 連絡先 | E5: 090-1234-5678 | L5: 連絡先 | N5: 090-XXXX-YYYY | X5: 三為契約(仲介なし) | AB5: 紙(印紙必要) | AC5: 売主
C6: 住所 | E6: 埼玉県さいたま市浦和区高砂1-2-3ライオンズマンション高砂第一121 | L6: 住所 | N6: 東京都葛飾区高砂5-41-3 | X6: その他 | AC6: 買主
C7: 契約の流れ | E7: 通常売買(仲介なし)→所有権移転→売却 | L7: 契約の流れ | N7: 通常売買(仲介なし)→所有権移転→売却 | AC7: 司法書士
C8: 司法書士 | E8: バイセル手配(公道事務所) | L8: 司法書士 | N8: バイセル手配(公道事務所) | AC8: その他
C9: 購入金額 | E9: ='②（土地・建物）事業収支シート'!M29 | L9: 売却金額 | N9: ='②（土地・建物）事業収支シート'!M22
C10: 購入手付金 | E10: 100000 | L10: 売却手付金 | N10: 100000
C11: 購入残代金 | E11: =E9-E10 | L11: 売却残代金 | N11: =N9-N10
C12: 備考 | L12: 備考
C13: 購入契約日 | E13: ='②（土地・建物）事業収支シート'!H6 | L13: 売却契約日 | N13: ='②（土地・建物）事業収支シート'!H7
C14: 時間 | E14: 0.41666667 | L14: 時間 | N14: 0.41666667
C15: 契約スタイル | E15: 対面契約 | L15: 契約スタイル | N15: 対面契約
C16: 参加者 | E16: 江藤、営業、仲介、売主 | L16: 参加者 | N16: 江藤、営業、仲介、買主
C17: 場所(住所) | E17: 埼玉県大宮区 | L17: 場所(住所) | N17: 埼玉県大宮区
C18: Google mapリンク | E18: http | L18: Google mapリンク | N18: http
C19: 手付金 | E19: =E10 | L19: 手付金 | N19: =N10
C20: 手付金 振込先口座 | E20: 埼玉縣信用金庫 浦和支店 普通 1234567 ムラカミムネタカ | L20: 手付金 着金口座 | N20: XXXX XX支店 普通 XXXXX カ）ビーアンドエスエステート
C21: その他支払金（ ） | E21: 0 | L21: その他支払金（ ） | N21: 0
C22: 支払金 振込先口座 | E22: 埼玉りそな銀行 XXX | L22: 支払金 振込先口座 | N22: 埼玉りそな銀行 XXX
C23: 印鑑＆法人代表セット | E23: 法人印、代表個人印、代表身分証明書 | I23: 誰が？ | J23: 江藤 | L23: 印鑑＆法人代表セット | N23: 法人印、代表個人印、代表身分証明書 | R23: 誰が？ | S23: 江藤
C24: 持ち物1 | E24: 手付金領収書 | I24: 誰が？ | J24: 仲介 | L24: 持ち物1 | N24: 手付金領収書 | R24: 誰が？ | S24: 担当営業
C25: 持ち物2 | I25: 誰が？ | L25: 持ち物2 | R25: 誰が？
C26: 持ち物3 | I26: 誰が？ | L26: 持ち物3 | R26: 誰が？
C27: 持ち物4 | I27: 誰が？ | L27: 持ち物4 | R27: 誰が？
C28: 持ち物5 | I28: 誰が？ | L28: 持ち物5 | R28: 誰が？
C29: 備考 | L29: 備考
C30: 購入契約日 | E30: ='②（土地・建物）事業収支シート'!K6 | L30: 売却契約日 | N30: ='②（土地・建物）事業収支シート'!K7
C31: 時間 | E31: 0.41666667 | L31: 時間 | N31: 0.41666667
C32: 契約スタイル | E32: 対面契約 | L32: 契約スタイル | N32: 対面契約
C33: 参加者 | E33: 江藤、営業、仲介、売主 | L33: 参加者 | N33: 江藤、営業、仲介、買主
C34: 場所(住所) | E34: 埼玉県大宮区 | L34: 場所(住所) | N34: 埼玉県大宮区
C35: Google mapリンク | E35: http | L35: Google mapリンク | N35: http
C36: 残代金 | E36: =E9-E19 | L36: 残代金 | N36: =N9-N19
C37: 残代金 振込先口座 | E37: 埼玉縣信用金庫 浦和支店 普通 1234567 ムラカミムネタカ | L37: 残代金 着金口座 | N37: XXXX XX支店 普通 XXXXX カ）ビーアンドエスエステート
C38: 固都税精算金 | E38: 10000 | J38: =E36+E38 | L38: 固都税精算金 | N38: 10000 | S38: =N36+N38
C39: 精算金 振込先口座 | E39: 埼玉縣信用金庫 浦和支店 普通 1234567 ムラカミムネタカ | L39: 精算金 着金口座 | N39: XXXX XX支店 普通 XXXXX カ）ビーアンドエスエステート
C40: 仲介手数料 | E40: ='②（土地・建物）事業収支シート'!H33+'②（土地・建物）事業収支シート'!I33 | L40: 仲介手数料 | N40: ='②（土地・建物）事業収支シート'!H57+'②（土地・建物）事業収支シート'!I57
...

Sheet 購入時
AH2: 令和 | AK2: 6 | AN2: 年 | AP2: 8 | AR2: 月 | AT2: 19 | AV2: 日
A5: 取引成立台帳（土地、土地建物、借地権付建物売買）
B11: 物 件 区 分 | H11: 土地建物（中古）売買 | U11: 登録年月日 | AA11: ='②（土地・建物）事業収支シート'!H6 | AN11: 契約区分 | AT11: 売買
B13: 成立年月日 | H13: ='②（土地・建物）事業収支シート'!K6 | U13: 引渡年月日 | AA13: =H13 | AN13: 取引態様 | AT13: 買主
B15: 売 主 | D15: 氏 名 | AI15: TEL：
D17: 住 所
D19: 代理人氏名 | AI19: TEL：
D21: 代理人住所
B23: 買 主 | D23: 氏 名 | H23: 株式会社B&Sエステート | AI23: TEL：
D25: 住 所 | H25: 埼玉県さいたま市大宮区宮町四丁目38番地4
D27: 代理人氏名 | AI27: TEL：
D29: 代理人住所
B32: 土 地 | D32: 所在・地番 | H32: =①物件情報入力シート!C4
D34: 権利種類 | H34: ■ | I34: 所有権 | M34: □ | N34: 借地権（賃借権） | V34: □ | W34: 借地権（地上権） | AE34: 地 目 | AI34: 公簿 | AK34: 宅地 | AP34: 現況 | AR34: 宅地
D36: 地 積 | H36: （登記簿） | M36: =①物件情報入力シート!C5 | AA36: ㎡ | AC36: （実 測） | AV36: ㎡
D38: 借地権の場合 借地対象面積 | O38: - | AA38: ㎡
D40: 都市計画 | H40: 市街化区域 | X40: 用途地域 | AB40: =①物件情報入力シート!C6
D42: 地域・地区・街区 | AB42: 建蔽率 | AF42: =①物件情報入力シート!C7 | AK42: ％ | AM42: 容積率 | AQ42: =①物件情報入力シート!C8 | AV42: ％
D44: 形 状 | H44: 整形地
D46: 位 置 | H46: 間口6.0m
D48: 設備等 | H48: なし
B50: 建 物 | D50: 所 在 | H50: =①物件情報入力シート!C3 | AG50: 家屋番号
D52: 住居表示 | H52: =①物件情報入力シート!C4 | AG52: 附属建物 | AK52: 無 | AM52: （ | AW52: ）
D54: 種 類 | H54: 居宅 | R54: 構 造 | V54: =①物件情報入力シート!C14 | AJ54: 用 途 | AN54: 居宅
D56: 床面積 | H56: ■ | I56: 登記簿 | M56: 1階 | O56: =①物件情報入力シート!C17 | S56: ㎡・ | U56: 2階 | W56: =①物件情報入力シート!C18 | AA56: ㎡・ | AC56: 階 | AI56: ㎡・ | AK56: 階 | AQ56: ㎡・
H58: □ | M58: 階 | S58: ㎡・ | U58: 階 | AA58: ㎡・ | AC58: 階 | AI58: ㎡ | AP58: 合計 | AR58: =O56+W56+AE56 | AV58: ㎡
D60: 建築時期 | H60: ■ | I60: 昭和 | N60: 年 | R60: 月 | V60: 日新築 | Z60: （ | AA60: 増築 | AD60: 昭和 | AI60: 年 | AM60: 月 | AO60: ） | AP60: ・ | AR60: □ | AS60: 不詳
B62: 宅建業者売主の新築住宅の場合 | L62: 販売瑕疵負担割合 | T62: - | W62: ％ | Y62: 住宅瑕疵担保責任保険法人名 | AL62: -
B65: 取引条件 | D65: 売買金額 | U65: （左記売買代金のうち土地価格） | AM65: ='②（土地・建物）事業収支シート'!H29+'②（土地・建物）事業収支シート'!H28 | AV65: 円
H67: ='②（土地・建物）事業収支シート'!M29 | S67: 円 | U67: （左記売買代金のうち建物価格） | AM67: ='②（土地・建物）事業収支シート'!H30 | AV67: 円
U69: （左記売買代金のうち消費税等相当額） | AM69: ='②（土地・建物）事業収支シート'!I30 | AV69: 円
D71: 手付金 | H71: ='②（土地・建物）事業収支シート'!H28 | R71: 円 | T71: 内金① | AG71: 円 | AI71: 内金② | AV71: 円
D73: 交換差金 | H73: □ | I73: 支払う | M73: □ | N73: 受領する | S73: （差金額） | AF73: 円 | AH73: （このうち消費税相当額） | AV73: 円
D75: 交換物件の内容
B78: 取引報酬額 | D78: 仲介 手数料 | H78: 日 付 | T78: 売主より
H80: 金 額 | R80: 円 | T80: (税率) | Y80: ％ | AA80: 消費税 | AE80: =L80*W80*0.01 | AJ80: 円 | AL80: 合 計 | AP80: =L80+AE80 | AV80: 円
H82: 日 付 | T82: 買主より
H84: 金 額 | R84: 円 | T84: (税率) | Y84: ％ | AA84: 消費税 | AE84: =L84*W84*0.01 | AJ84: 円 | AL84: 合 計 | AP84: =L84+AE84 | AV84: 円
H86: 収入合計 | L86: =AP80+AP84 | T86: 円 | V86: （内訳） | Z86: 税抜合計 | AD86: =L80+L84 | AJ86: 円 | AL86: 消費税合計 | AP86: =AE80+AE84 | AV86: 円
D88: 支払 手数料 | H88: 日 付 | L88: ='②（土地・建物）事業収支シート'!K6 | T88: 支払先
...

Sheet 売却時
AH2: 令和 | AK2: 7 | AN2: 年 | AP2: 7 | AR2: 月 | AT2: 25 | AV2: 日
A5: 取引成立台帳（土地、土地建物、借地権付建物売買）
B11: 物 件 区 分 | H11: 土地建物（中古）売買 | U11: 登録年月日 | AA11: ='②（土地・建物）事業収支シート'!H7 | AN11: 契約区分 | AT11: 売買
B13: 成立年月日 | H13: ='②（土地・建物）事業収支シート'!K7 | U13: 引渡年月日 | AA13: ='②（土地・建物）事業収支シート'!K7 | AN13: 取引態様 | AT13: 売主
B15: 売 主 | D15: 氏 名 | H15: 株式会社B&Sエステート | AI15: TEL：
D17: 住 所 | H17: 埼玉県さいたま市大宮区宮町四丁目38番地4
D19: 代理人氏名 | AI19: TEL：
D21: 代理人住所
B23: 買 主 | D23: 氏 名 | AI23: TEL：
D25: 住 所
D27: 代理人氏名 | AI27: TEL：
D29: 代理人住所
B32: 土 地 | D32: 所在・地番 | H32: =①物件情報入力シート!C4
D34: 権利種類 | H34: ■ | I34: 所有権 | M34: □ | N34: 借地権（賃借権） | V34: □ | W34: 借地権（地上権） | AE34: 地 目 | AI34: 公簿 | AK34: 宅地 | AP34: 現況 | AR34: 宅地
D36: 地 積 | H36: （登記簿） | M36: =①物件情報入力シート!C5 | AA36: ㎡ | AC36: （実 測） | AV36: ㎡
D38: 借地権の場合 借地対象面積 | O38: - | AA38: ㎡
D40: 都市計画 | H40: 市街化区域 | X40: 用途地域 | AB40: =①物件情報入力シート!C6
D42: 地域・地区・街区 | AB42: 建蔽率 | AF42: =①物件情報入力シート!C7 | AK42: ％ | AM42: 容積率 | AQ42: =①物件情報入力シート!C8 | AV42: ％
D44: 形 状 | H44: 整形地
D46: 位 置 | H46: 間口6.0m
D48: 設備等 | H48: なし
B50: 建 物 | D50: 所 在 | H50: =①物件情報入力シート!C3 | AG50: 家屋番号
D52: 住居表示 | H52: =①物件情報入力シート!C4 | AG52: 附属建物 | AK52: 無 | AM52: （ | AW52: ）
D54: 種 類 | R54: 構 造 | V54: =①物件情報入力シート!C14 | AJ54: 用 途
D56: 床面積 | H56: ■ | I56: 登記簿 | M56: 1階 | O56: =①物件情報入力シート!C17 | S56: ㎡・ | U56: 2階 | W56: =①物件情報入力シート!C18 | AA56: ㎡・ | AC56: 階 | AI56: ㎡・ | AK56: 階 | AQ56: ㎡・
H58: □ | M58: 階 | S58: ㎡・ | U58: 階 | AA58: ㎡・ | AC58: 階 | AI58: ㎡ | AP58: 合計 | AR58: =O56+W56+AE56 | AV58: ㎡
D60: 建築時期 | H60: ■ | I60: 平成 | N60: 年 | R60: 月 | V60: 日新築 | Z60: （ | AI60: 年 | AM60: 月 | AO60: ） | AP60: ・ | AR60: □ | AS60: 不詳
B62: 宅建業者売主の新築住宅の場合 | L62: 販売瑕疵負担割合 | T62: - | W62: ％ | Y62: 住宅瑕疵担保責任保険法人名 | AL62: -
B65: 取引条件 | D65: 売買金額 | U65: （左記売買代金のうち土地価格） | AM65: =H67 | AV65: 円
H67: ='②（土地・建物）事業収支シート'!M22 | S67: 円 | U67: （左記売買代金のうち建物価格） | AV67: 円
U69: （左記売買代金のうち消費税等相当額） | AV69: 円
D71: 手付金 | R71: 円 | T71: 内金① | AG71: 円 | AI71: 内金② | AV71: 円
D73: 交換差金 | H73: □ | I73: 支払う | M73: □ | N73: 受領する | S73: （差金額） | AF73: 円 | AH73: （このうち消費税相当額） | AV73: 円
D75: 交換物件の内容
B78: 取引報酬額 | D78: 仲介 手数料 | H78: 日 付 | T78: 売主より
H80: 金 額 | R80: 円 | T80: (税率) | Y80: ％ | AA80: 消費税 | AE80: =L80*W80*0.01 | AJ80: 円 | AL80: 合 計 | AP80: =L80+AE80 | AV80: 円
H82: 日 付 | T82: 買主より
H84: 金 額 | R84: 円 | T84: (税率) | Y84: ％ | AA84: 消費税 | AE84: =L84*W84*0.01 | AJ84: 円 | AL84: 合 計 | AP84: =L84+AE84 | AV84: 円
H86: 収入合計 | L86: =AP80+AP84 | T86: 円 | V86: （内訳） | Z86: 税抜合計 | AD86: =L80+L84 | AJ86: 円 | AL86: 消費税合計 | AP86: =AE80+AE84 | AV86: 円
D88: 支払 手数料 | H88: 日 付 | T88: 支払先
...

Sheet 購入申込書(B&S)
A1: 購 入 申 込 書
J3: =TODAY()+1
A4: 売主 様
A6: 下記表示の不動産を、下記条件にて購入致します。
A8: 不動産の表示 | C8: 所在地番 | E8: =①物件情報入力シート!C4
C9: 土地面積 | E9: =①物件情報入力シート!C5 | G9: ㎡ | H9: 建物面積 | J9: =①物件情報入力シート!C17+①物件情報入力シート!C18+①物件情報入力シート!C19 | L9: ㎡
A10: 所有者（売主） | C10: 売 主 様
A11: 買 受 条 件 | C11: 売買金額 | E11: ='②（土地・建物）事業収支シート'!M29
C12: 支払条件 | E12: 手付金 | F12: ='②（土地・建物）事業収支シート'!H28
E13: 中間金
E14: 残代金 | F14: =E11-F12 | J14: 決済時に売主指定口座へ振り込み
C15: 融資利用 | E15: 有・無 | J15: 融資利用特約 | L15: 有・無
C16: その他 | E16: ・売主様の契約不適合責任免責。 ・内外動産物含め現況有姿で購入いたします。 ・決済前に販売活動を開始するものとします。 ・決済前に調査等により敷地内及び建物内への立入をご承諾頂けるものとします。 ・近隣トラブル、越境問題がないこと。 ・第三者の為の売買契約、決済猶予は契約から6ヶ月間とすること。 ・司法書士は買主にて指定させていただきます。
G18: ≪申込人≫
G20: 住 所 | H20: 埼玉県さいたま市大宮区宮町4-38-4
H22: 株式会社B&Sエステート
G23: 氏 名 | H23: 代表取締役 江 藤 哲 寛

Sheet 不動産購入申込書 (榎本工務店)
A1: 不動産購入申込書
F3: =TODAY()+2
A4: 所有者 様
E5: 住所 和光市白子3-6-13
E7: 氏名（有）榎本工務店 榎本 俊一 | H7: ㊞
A9: 私は、下記の不動産を以下の条件にて購入したく申し込みいたします。
A11: 記
A13: １．売買物件の表示
A14: 所 在 | B14: =①物件情報入力シート!C4
A15: 土 地 | B15: 土地面積 | C15: =①物件情報入力シート!C5
A16: 建 物 | B16: 床面積 | C16: １階 | D16: =①物件情報入力シート!C17 | E16: ２階 | F16: =①物件情報入力シート!C18 | G16: ３階 | H16: =①物件情報入力シート!C19
B17: (その他) | G17: 延床面積 | H17: =D16+F16+H16
A19: ２．売買代金及び支払い条件
A20: 購入価格 | C20: 売買代金総額 | F20: 4200000 | H20: 円也
A21: 手付金 | C21: 本契約締結時 | F21: =F20*0.05 | H21: 円也
A22: 残代金 | C22: 所有権移転時 | F22: =F20-F21 | H22: 円也
A23: 契約時期 | C23: ご相談 | E23: 引渡時期 | G23: ご相談
A24: 融資利用 | C24: 融資利用なし
A25: 備考
A26: その他条件 | C26: 残置物はすべて売主様負担で処分をお願いします。
C27: 売主様負担にて確定測量完了後の決済とさせていただきます。
C28: 契約不適合責任3か月でお願いいたします。
A31: ※本書の有効期限 | D31: =TODAY()+30 | F31: まで

Sheet 不動産買付申込書（一藤）
A1: 不動産買付申込書
A2: 売 主 殿
A4: 物件の表示
A5: 所在地 | B5: =①物件情報入力シート!C4
A6: 構 造
A8: 上記記載物件を下記条項により申し込みすることを証明致します。
A9: 尚、下記条項にて成約に至った場合は、別途売買契約書を作成し、署名・押印致します。
A11: 買付価格 | B11: 1000000
A12: 手 付 金 | B12: 相談の上、決定
A13: 契 約 日 | B13: 相談の上、決定
A14: 決 済 日 | B14: 相談の上、決定
A15: 取引条件 | B15: 公簿売買
A16: 有効期限 | B16: =TODAY()+30
A17: その他 | B17: ・現地内見の上、問題ないことを確認の上
B18: ・火災保険契約継承を希望
B19: ・残置物は売主様にてご対応をお願いいたします。
B20: ・境界明示（確定測量）
B21: ・買主希望の条件でのローン特約
A24: =TODAY()-3
A26: 買付人
A27: （住所）茨城県古河市大山1740-223
A29: （氏名）株式会社一藤 代表取締役 伊東誠一

Sheet 買付証明書（フジタケ）
A1: 買付証明書
AB3: =TODAY()
A5: 売主 | M5: 様
U6: 住所 埼玉県狭山市水野1013-16
U8: 氏名 有限会社フジタケ 佐藤 玲二 | AG8: 印
B12: 私は、下記不動産を、下記の条件にて購入したく、買い付けることを証明いたします。
Q14: 記
A16: １．物件 | G16: 所 在 | K16: =①物件情報入力シート!C4
G17: 土 地 | K17: =①物件情報入力シート!C5 | P17: ㎡ | Q17: （ | R17: =K17/3.30578 | V17: 坪 | W17: ）
G18: 建 物 | K18: =①物件情報入力シート!C17+①物件情報入力シート!C18+①物件情報入力シート!C19 | P18: ㎡ | Q18: （ | R18: =K18/3.30578 | V18: 坪 | W18: ）
A20: ２．条件 | G20: 購入価格 | L20: 金 | N20: 1350000 | T20: 円也
G21: 手付金 | L21: 金 | N21: 0 | T21: 円也 | W21: ※購入価格に充当
A23: ３．支払方法 | G23: ・現金 | L23: ・銀行融資
A25: ４．有効期間 | G25: 本書面の有効期間は、買付提出日より１か月間となります。
A27: ５．その他条件
A28: 残置物がある場合はすべて売主様で撤去をお願いいたします。
A29: 残置物撤去後に契約決済とします。
A30: 残置物撤去後に瑕疵が見られた場合は，買付金額を訂正させていただく場合がございます。
A31: 境界非明示で構いません。
AF33: 以上

Sheet 買付証明書(オプタプランニング)
A1: 買付証明書
X3: =TODAY()+1
A5: 売主 | M5: 様
T6: 住所 東京都世田谷区経堂2-27-10
T8: 氏名 合同会社オプタプランニング 代表社員 中本 雄土 | AG8: 印
B12: 私は、下記不動産を、下記の条件にて購入したく、買い付けることを証明いたします。
Q14: 記
A16: １．物件 | G16: 物件名 | K16: =①物件情報入力シート!C3
G17: 所 在 | K17: =①物件情報入力シート!C4
G18: 土 地 | K18: =①物件情報入力シート!C5 | P18: ㎡ | Q18: （ | R18: =K18/3.30578 | V18: 坪 | W18: ）
G19: 建 物 | K19: =①物件情報入力シート!C17+①物件情報入力シート!C18+①物件情報入力シート!C19 | P19: ㎡ | Q19: （ | R19: =K19/3.30578 | V19: 坪 | W19: ）
A21: ２．条件 | G21: 購入価格 | L21: 金 | N21: 500000 | T21: 円也
G22: 手付金 | L22: 金 | N22: 100000 | T22: 円也 | W22: ※購入価格に充当
A24: ３．支払方法 | G24: ・現金 | L24: ・銀行融資
A26: ４．有効期間 | G26: 本書面の有効期間は | N26: =TODAY()+35 | U26: までとします
A28: ５．その他条件
A29: ・残置物は売主様にて撤去をお願いいたします。
AF34: 以上

Sheet 収支計算シートのルール
A1: 収支計算シート使用の流れ
A2: 【査定開始前】
A3: ・必ず最新版を使用する
A5: 【買付通過後】
A6: ・江藤さんに案件のNo.を確認する
A7: ・エクセルのタイトルを下記のルールで変更する
B8: 数字は全て半角
B9: 市区町村から住所表記で最後まで記載
B10: 最後の日付はNoを割り振られた日
A11: 〈例〉
A12: 044.足立区大谷田1-10-7_転売用収支計算シート_(20241019)
A13: ・エクセルの「持ち物リスト」シートのB1のセルのNo.も記載
A14: ・Teams>チーム>フルコミ>02-フルコミ検討資料>20_収支計算シートにアップロードする。 以降はそこに置いてあるものを正とする。
A15: (個人フォルダに置いてあるものは参考)
A16: ・Teams>チーム>フルコミ>02-フルコミ検討資料>売買予定表に必要事項を記載する。

Sheet 変更履歴
A1: 編集履歴
A2: 日時 | B2: 編集者 | C2: ver | D2: 内容
A3: 45437 | B3: 伊東 | C3: 共通化仕様ver3.0 | D3: 榎本さんのエクセルを改良
A4: 45437 | B4: 伊東 | C4: 共通化仕様ver3.1 | D4: ・②シート目の名称変更 ・②シート目、G71&H71に業務委託料の項目を追加 ・②シート目H10の単位修正(円/坪→円) ・①物件情報入力シートC34に国交省HPのハイパーリンク追加。C35に国交省HPの確認についてのコメント追加。
A5: 45451 | B5: 伊東 | C5: 共通化仕様ver3.2 | D5: 入金予定日、支払い予定日の列をアップデート。 白抜きは自動入力。黄色タブは入力が無いとアラートが出るように変更。
A6: 45452 | B6: 伊東 | C6: 共通化仕様ver3.3 | D6: ・②シート目 B29,B30の関数を修正 ・エクセルタイトルを修正
A7: 45502 | B7: 伊東 | C7: 共通化仕様ver3.4 | D7: ・固定資産税日割り計算の日数を365→366に変更 ・建蔽率容積率を求めるリンクを追加 ・年間固定資産税についてメモ書きに追加 田舎の戸建5万円、都心の戸建10万円 ・実勢価格係数 田舎1.1 中間1.5 都市2.0 ・道路係数→容積率低減係数に変更。デフォルトで0.4を入れておく
A8: 45660 | B8: 伊東 | C8: 共通化仕様ver3.5 | D8: ・固定資産税日割り計算の日数を366→365に変更 ・シート② M2セルの日付計算の引数を2026/1/1に変更 ・シート①の件築年数(N,O列)を令和7年版にアップデート ・年間固定資産税は固定資産税路線価の2%をデフォルトと設定(土地1.4%＋建物(耐用年数オーバー)想定) ・相続税路線価入力欄にメモ書き追加 相続税路線価設定がない場合は固定資産税路線価÷0.7×0,8 ・購入時仲介手数料についてメモ書き追加
A9: 45761 | B9: 伊東 | C9: 共通化仕様ver3.6 | D9: ・持ち物リストシートを追加 ・取引台帳(購入時、売却時)シートを追加 ・購入申込書シートを追加 ・収支計算シートのルールを追加
C10: 共通化仕様ver3.7 | D10: ・業務委託料割合を入力できるように変更、シート② M69セルに追加 ・シート② M2セルの日付計算の引数を2027/1/1に変更
A11: 46074 | B11: 伊東 | C11: 共通化仕様ver3.8 | D11: ・シート① 築年数のリストを2026年verに反映 ・シート① C26セル相続税路線価については固定資産税から算出する式をデフォルトで入力、相続税路線価設定がある場合は手入力
